Workbook

Sheet ① 안내
A1: 한→영 소설 MT 평가표
A2: 한→영 웹소설 번역 프롬프트 평가를 위한 평가표입니다. 운영 가이드·매뉴얼과 함께 사용하세요.
A4: 시트 구성
A5: ① 안내 | B5: 본 시트. 평가 기준·운영 방식 요약
A6: ② 카테고리 정의 | B6: 14개 카테고리의 정의·예시·강도 점수 기준
A7: ③ 평가 입력 | B7: 문장 단위 평가 입력 시트 (메인 작업 시트)
A8: ④ 정성 평가 | B8: 장면 단위 정성 7항목 평가
A9: ⑤ 결과 대시보드 | B9: 정량·정성 결과 자동 산출
A10: ⑥ 버전 비교 | B10: 직전 버전 대비 변화량·나빠진 항목 추적
A11: ⑦ 기타 사례 누적 | B11: "기타" 분류 사례 모아 신규 카테고리 검토
A12: ⑧ 평가자 일치율 | B12: 본 평가 전 평가자 기준 맞추기
A13: ⑨ 본 평가 비교 | B13: 두 평가자 결과 자동 비교·합산
A15: 정량 기준
A16: 전체 문장 중 수정한 문장 비율 | B16: ≤ 50% — 카테고리 1~14 전체 (강도 ≥1)
A17: 의미 오류 수정률 | B17: ≤ 20% — 카테고리 3·4·5·6·7·9·10
A18: 형식 오류 수정률 | B18: ≤ 15% — 카테고리 1·2·8·11·13
A19: 흐름 오류 발생률 | B19: ≤ 10% — 카테고리 12
A20: 수정 없이 넘긴 문장 비율 | B20: ≥ 30% — 카테고리 1~14 모두 강도 0인 문장
A21: 기타 (14번) | B21: 총 수정률에만 포함, 의미·형식·흐름 어느 그룹에도 속하지 않음
A22: 나빠진 항목 표시 | B22: 직전 버전 대비 어떤 카테고리든 +2%p 이상 늘어나면 표시
A23: 결과 흔들림 검사 | B23: 동일 프롬프트 2~3회 반복 시 차이 ≤ 5%p

Sheet ② 카테고리 정의
A1: # | B1: 카테고리 | C1: 정의 | D1: 한→영 특화 포인트 | E1: 강도 1 예시 | F1: 강도 2 예시 | G1: 강도 3 예시 | H1: 집계 그룹
A2: 1 | B2: 오타·표기 오류 | C2: 오탈자, 단어 누락, 잘못된 철자 (accent 누락 포함, 예: naïve에 일반 i 사용), 말더듬 철자 | D2: 미국식 영어 철자, CMOS 기준 표기, accent 처리 | E2: 경미한 오탈자 1곳 | F2: 복수 단어 철자 오류 | G2: 인명·지명 오기로 독자 혼란 | H2: 형식 오류
A3: 2 | B3: 문법·문장 구조 오류 | C3: dangling modifier, 병렬 구조 불일치, 시제 일관성, 조동사 오용 | D3: 한국어 SOV 어순 잔존으로 영어 문법이 깨지는 경우 | E3: 쉼표 위치 부적절 | F3: 현수 수식어·병렬 구조 명확한 오류 | G3: 문장 구조 붕괴로 의미 파악 불가 | H3: 형식 오류
A4: 3 | B4: 오역 | C4: 의미 왜곡, 발화자 혼동, 누락, 한국어 다의어 문맥 미반영 | D4: 한국어 다의어를 문맥과 다르게 옮기는 경우, 화자 착각 | E4: 뉘앙스 미세 차이 | F4: 의미 일부 왜곡 또는 화자 혼동 | G4: 핵심 플롯 왜곡, 캐릭터 관계 오인 | H4: 의미 오류
A5: 4 | B5: 톤·감정 왜곡 | C5: 캐릭터 감정 과장/축소, 장면 분위기 불일치 (예: 부드러운 장면에 rage·seized 사용) | D5: 원문 톤 왜곡, 감정 과장/축소 | E5: 약간의 톤 차이 | F5: 감정 명확히 과장 또는 축소 | G5: 원문과 정반대 감정 전달 | H5: 의미 오류
A6: 5 | B6: 호칭·경칭 오류 | C6: Your Grace/my lord/miss 등 부적절 사용, 대소문자 일관성 | D6: 작품 내 사회적 지위·계급에 맞는 호칭 선택, 서술에서 호칭 사용 금지(가이드 규칙) | E6: 호칭 대소문자 경미한 흔들림 | F6: 신분에 안 맞는 호칭 사용 | G6: 권력 관계 완전히 붕괴되는 호칭 오류 | H6: 의미 오류
A7: 6 | B7: 직역체·부자연스러움 | C7: 한국어 어순(SOV) 잔존, 비관용적 영어, 어색한 표현, 논리적 전개 부족, 단어/표현 선정 문제 | D7: "처음부터 영어로 쓰인 소설처럼 읽혀야 한다"는 가이드 핵심 원칙 위반 | E7: 약간 어색한 표현, 단어/표현 선정 문제 | F7: 직역 티가 명확, 관용적이지 않음 | G7: 영어 화자가 거의 쓰지 않는 문장 | H7: 의미 오류
A8: 7 | B8: AI 특유 과잉 표현 | C8: predatory smile, a surge of, devoid of 등 반복적 AI 투 표현, 불필요한 수식어 과다 | D8: 가이드에서 명시적으로 삭제·수정 지시한 AI 표현 패턴 | E8: AI 표현 1~2개 잔존 | F8: AI 표현 다수 반복 사용 | G8: 문단 전체가 AI 투로 캐릭터성·톤 훼손 | H8: 의미 오류
A9: 8 | B9: 대사 태그·화자 구분 | C9: 화자 불분명, spoke 사용, 대사-행동 분리 부적절, 문단 구조 오류 | D9: 화자 바뀔 때 새 문단 미사용, 행동을 대사 태그로 통합 안 함, 대사 서식 오류 | E9: 대사 태그 경미한 부적절 | F9: 화자 구분 안 되는 문단 구조 | G9: 대화 흐름 완전히 깨짐 | H9: 형식 오류
A10: 9 | B10: 비유·관용어 현지화 | C10: 한국어 비유·속담·사자성어의 직역, 영어권에서 안 통하는 비유, 의성어·의태어 처리, 차별적·무감한 표현 (vegetable·homeless 등), 사회적 민감도 미고려 | D10: 한국어 비유 직역 + 문화적 감수성 통합 카테고리 | E10: 비유 살짝 어색 의성어/의태어 그대로 번역 | F10: 한국어 비유 직역으로 의미 전달 부족 또는 민감한 표현 | G10: 비유 직역·감수성 위반으로 장면 붕괴 | H10: 의미 오류
A11: 10 | B11: 설정·세계관 위반 | C11: 용어집 미반영, 시대 부적합 어휘 (시대물에 현대어), 호칭 일관성, 동일 인물·용어·표현 불일치, 대소문자 표기 불통일 | D11: 설정 + 일관성 통합 카테고리 | E11: 용어집 미세 불일치, 호칭 대소문자 오류 | F11: 용어집 명확히 누락 또는 일관성 깨짐 | G11: 세계관 핵심 설정 위반, 독자 혼란 | H11: 의미 오류
A12: 11 | B12: 스타일 가이드·표기 | C12: 구두점 (CMOS 기준), 대시·말줄임표, 숫자·단위 표기, 이탤릭체, 딩커스 | D12: Oxford comma, curly quotes, em-dash/en-dash, 야드파운드법, 시간·날짜 표기, 물결표 금지 | E12: 경미한 구두점 오류 | F12: 가이드 명백 위반 | G12: 가독성 심각 저하 | H12: 형식 오류
... A15: 14 | B15: 기타 | C15: 위 항목에 포함되지 않으나 번역 품질에 영향 | D15: 신규 카테고리 후보 누적용. ⑦ 시트에 사례 기록 | E15: 경미한 기타 문제 | F15: 명확한 기타 문제 | G15: 심각한 기타 문제 | H15: 기타
A18: 강도 점수 기준
A19: 점수 | B19: 의미 | C19: 판정 기준
A20: 0 | B20: 문제 없음 | C20: 수정 불필요
A21: 1 | B21: 경미 | C21: 다듬으면 좋으나 의미 전달 OK
A22: 2 | B22: 보통 | C22: 검수자가 명확히 수정해야 함
A23: 3 | B23: 치명 | C23: 독자 이해 실패, 캐릭터 붕괴 등

Sheet ③ 평가 입력
A1: 작품·문장 번호 | B1: 원문 (한국어) | C1: MT본 (영어) | D1: 검수본 (수정 결과) | E1: 카테고리별 강도 (0~3) | S1: 문장 단위 집계 | Y1: 비고
E2: 1.오타 | F2: 2.문법 | G2: 3.오역 | H2: 4.톤감정 | I2: 5.호칭 | J2: 6.직역 | K2: 7.AI표현 | L2: 8.대사태그 | M2: 9.비유관용 | N2: 10.설정 | O2: 11.스타일 | P2: 12.흐름중복 | Q2: 13.서술규칙 | R2: 14.기타 | S2: 수정여부 | T2: 의미오류 | U2: 형식오류 | V2: 흐름오류 | W2: 미수정 | X2: 강도합
A3: 1 | S3: =IF(SUM(E3:R3)>0,1,0) -> 0 | T3: =IF(MAX(G3,H3,I3,J3,K3,M3,N3)>0,1,0) -> 0 | U3: =IF(MAX(E3,F3,L3,O3,Q3)>0,1,0) -> 0 | V3: =IF(P3>0,1,0) -> 0 | W3: =IF(AND(B3<>"",S3=0),1,0) -> 0 | X3: =SUMPRODUCT((E3:R3=1)*0.3)+SUMPRODUCT((E3:R3=2)*0.7)+SUMPRODUCT((E3:R3=3)*1.5) -> 0
A4: 2 | S4: =IF(SUM(E4:R4)>0,1,0) -> 0 | T4: =IF(MAX(G4,H4,I4,J4,K4,M4,N4)>0,1,0) -> 0 | U4: =IF(MAX(E4,F4,L4,O4,Q4)>0,1,0) -> 0 | V4: =IF(P4>0,1,0) -> 0 | W4: =IF(AND(B4<>"",S4=0),1,0) -> 0 | X4: =SUMPRODUCT((E4:R4=1)*0.3)+SUMPRODUCT((E4:R4=2)*0.7)+SUMPRODUCT((E4:R4=3)*1.5) -> 0
A5: 3 | S5: =IF(SUM(E5:R5)>0,1,0) -> 0 | T5: =IF(MAX(G5,H5,I5,J5,K5,M5,N5)>0,1,0) -> 0 | U5: =IF(MAX(E5,F5,L5,O5,Q5)>0,1,0) -> 0 | V5: =IF(P5>0,1,0) -> 0 | W5: =IF(AND(B5<>"",S5=0),1,0) -> 0 | X5: =SUMPRODUCT((E5:R5=1)*0.3)+SUMPRODUCT((E5:R5=2)*0.7)+SUMPRODUCT((E5:R5=3)*1.5) -> 0 | Y5: 어순
A6: 4 | S6: =IF(SUM(E6:R6)>0,1,0) -> 0 | T6: =IF(MAX(G6,H6,I6,J6,K6,M6,N6)>0,1,0) -> 0 | U6: =IF(MAX(E6,F6,L6,O6,Q6)>0,1,0) -> 0 | V6: =IF(P6>0,1,0) -> 0 | W6: =IF(AND(B6<>"",S6=0),1,0) -> 0 | X6: =SUMPRODUCT((E6:R6=1)*0.3)+SUMPRODUCT((E6:R6=2)*0.7)+SUMPRODUCT((E6:R6=3)*1.5) -> 0 | Y6: wash over
A7: 5 | S7: =IF(SUM(E7:R7)>0,1,0) -> 0 | T7: =IF(MAX(G7,H7,I7,J7,K7,M7,N7)>0,1,0) -> 0 | U7: =IF(MAX(E7,F7,L7,O7,Q7)>0,1,0) -> 0 | V7: =IF(P7>0,1,0) -> 0 | W7: =IF(AND(B7<>"",S7=0),1,0) -> 0 | X7: =SUMPRODUCT((E7:R7=1)*0.3)+SUMPRODUCT((E7:R7=2)*0.7)+SUMPRODUCT((E7:R7=3)*1.5) -> 0
A8: 6 | S8: =IF(SUM(E8:R8)>0,1,0) -> 0 | T8: =IF(MAX(G8,H8,I8,J8,K8,M8,N8)>0,1,0) -> 0 | U8: =IF(MAX(E8,F8,L8,O8,Q8)>0,1,0) -> 0 | V8: =IF(P8>0,1,0) -> 0 | W8: =IF(AND(B8<>"",S8=0),1,0) -> 0 | X8: =SUMPRODUCT((E8:R8=1)*0.3)+SUMPRODUCT((E8:R8=2)*0.7)+SUMPRODUCT((E8:R8=3)*1.5) -> 0
A9: 7 | S9: =IF(SUM(E9:R9)>0,1,0) -> 0 | T9: =IF(MAX(G9,H9,I9,J9,K9,M9,N9)>0,1,0) -> 0 | U9: =IF(MAX(E9,F9,L9,O9,Q9)>0,1,0) -> 0 | V9: =IF(P9>0,1,0) -> 0 | W9: =IF(AND(B9<>"",S9=0),1,0) -> 0 | X9: =SUMPRODUCT((E9:R9=1)*0.3)+SUMPRODUCT((E9:R9=2)*0.7)+SUMPRODUCT((E9:R9=3)*1.5) -> 0 | Y9: sheer
A10: 8 | S10: =IF(SUM(E10:R10)>0,1,0) -> 0 | T10: =IF(MAX(G10,H10,I10,J10,K10,M10,N10)>0,1,0) -> 0 | U10: =IF(MAX(E10,F10,L10,O10,Q10)>0,1,0) -> 0 | V10: =IF(P10>0,1,0) -> 0 | W10: =IF(AND(B10<>"",S10=0),1,0) -> 0 | X10: =SUMPRODUCT((E10:R10=1)*0.3)+SUMPRODUCT((E10:R10=2)*0.7)+SUMPRODUCT((E10:R10=3)*1.5) -> 0 | Y10: exact same
A11: 9 | S11: =IF(SUM(E11:R11)>0,1,0) -> 0 | T11: =IF(MAX(G11,H11,I11,J11,K11,M11,N11)>0,1,0) -> 0 | U11: =IF(MAX(E11,F11,L11,O11,Q11)>0,1,0) -> 0 | V11: =IF(P11>0,1,0) -> 0 | W11: =IF(AND(B11<>"",S11=0),1,0) -> 0 | X11: =SUMPRODUCT((E11:R11=1)*0.3)+SUMPRODUCT((E11:R11=2)*0.7)+SUMPRODUCT((E11:R11=3)*1.5) -> 0 | Y11: amused 단어선정
A12: 10 | S12: =IF(SUM(E12:R12)>0,1,0) -> 0 | T12: =IF(MAX(G12,H12,I12,J12,K12,M12,N12)>0,1,0) -> 0 | U12: =IF(MAX(E12,F12,L12,O12,Q12)>0,1,0) -> 0 | V12: =IF(P12>0,1,0) -> 0 | W12: =IF(AND(B12<>"",S12=0),1,0) -> 0 | X12: =SUMPRODUCT((E12:R12=1)*0.3)+SUMPRODUCT((E12:R12=2)*0.7)+SUMPRODUCT((E12:R12=3)*1.5) -> 0 | Y12: perhaps 오역
A13: 11 | S13: =IF(SUM(E13:R13)>0,1,0) -> 0 | T13: =IF(MAX(G13,H13,I13,J13,K13,M13,N13)>0,1,0) -> 0 | U13: =IF(MAX(E13,F13,L13,O13,Q13)>0,1,0) -> 0 | V13: =IF(P13>0,1,0) -> 0 | W13: =IF(AND(B13<>"",S13=0),1,0) -> 0 | X13: =SUMPRODUCT((E13:R13=1)*0.3)+SUMPRODUCT((E13:R13=2)*0.7)+SUMPRODUCT((E13:R13=3)*1.5) -> 0
A14: 12 | S14: =IF(SUM(E14:R14)>0,1,0) -> 0 | T14: =IF(MAX(G14,H14,I14,J14,K14,M14,N14)>0,1,0) -> 0 | U14: =IF(MAX(E14,F14,L14,O14,Q14)>0,1,0) -> 0 | V14: =IF(P14>0,1,0) -> 0 | W14: =IF(AND(B14<>"",S14=0),1,0) -> 0 | X14: =SUMPRODUCT((E14:R14=1)*0.3)+SUMPRODUCT((E14:R14=2)*0.7)+SUMPRODUCT((E14:R14=3)*1.5) -> 0 | Y14: 어순 (of course 맨 끝에)
A15: 13 | S15: =IF(SUM(E15:R15)>0,1,0) -> 0 | T15: =IF(MAX(G15,H15,I15,J15,K15,M15,N15)>0,1,0) -> 0 | U15: =IF(MAX(E15,F15,L15,O15,Q15)>0,1,0) -> 0 | V15: =IF(P15>0,1,0) -> 0 | W15: =IF(AND(B15<>"",S15=0),1,0) -> 0 | X15: =SUMPRODUCT((E15:R15=1)*0.3)+SUMPRODUCT((E15:R15=2)*0.7)+SUMPRODUCT((E15:R15=3)*1.5) -> 0 | Y15: 현대어
A16: 14 | S16: =IF(SUM(E16:R16)>0,1,0) -> 0 | T16: =IF(MAX(G16,H16,I16,J16,K16,M16,N16)>0,1,0) -> 0 | U16: =IF(MAX(E16,F16,L16,O16,Q16)>0,1,0) -> 0 | V16: =IF(P16>0,1,0) -> 0 | W16: =IF(AND(B16<>"",S16=0),1,0) -> 0 | X16: =SUMPRODUCT((E16:R16=1)*0.3)+SUMPRODUCT((E16:R16=2)*0.7)+SUMPRODUCT((E16:R16=3)*1.5) -> 0 | Y16: 어순, 논리적 전개
A17: 15 | S17: =IF(SUM(E17:R17)>0,1,0) -> 0 | T17: =IF(MAX(G17,H17,I17,J17,K17,M17,N17)>0,1,0) -> 0 | U17: =IF(MAX(E17,F17,L17,O17,Q17)>0,1,0) -> 0 | V17: =IF(P17>0,1,0) -> 0 | W17: =IF(AND(B17<>"",S17=0),1,0) -> 0 | X17: =SUMPRODUCT((E17:R17=1)*0.3)+SUMPRODUCT((E17:R17=2)*0.7)+SUMPRODUCT((E17:R17=3)*1.5) -> 0
A18: 16 | S18: =IF(SUM(E18:R18)>0,1,0) -> 0 | T18: =IF(MAX(G18,H18,I18,J18,K18,M18,N18)>0,1,0) -> 0 | U18: =IF(MAX(E18,F18,L18,O18,Q18)>0,1,0) -> 0 | V18: =IF(P18>0,1,0) -> 0 | W18: =IF(AND(B18<>"",S18=0),1,0) -> 0 | X18: =SUMPRODUCT((E18:R18=1)*0.3)+SUMPRODUCT((E18:R18=2)*0.7)+SUMPRODUCT((E18:R18=3)*1.5) -> 0
A19: 17 | S19: =IF(SUM(E19:R19)>0,1,0) -> 0 | T19: =IF(MAX(G19,H19,I19,J19,K19,M19,N19)>0,1,0) -> 0 | U19: =IF(MAX(E19,F19,L19,O19,Q19)>0,1,0) -> 0 | V19: =IF(P19>0,1,0) -> 0 | W19: =IF(AND(B19<>"",S19=0),1,0) -> 0 | X19: =SUMPRODUCT((E19:R19=1)*0.3)+SUMPRODUCT((E19:R19=2)*0.7)+SUMPRODUCT((E19:R19=3)*1.5) -> 0 | Y19: 어순
A20: 18 | S20: =IF(SUM(E20:R20)>0,1,0) -> 0 | T20: =IF(MAX(G20,H20,I20,J20,K20,M20,N20)>0,1,0) -> 0 | U20: =IF(MAX(E20,F20,L20,O20,Q20)>0,1,0) -> 0 | V20: =IF(P20>0,1,0) -> 0 | W20: =IF(AND(B20<>"",S20=0),1,0) -> 0 | X20: =SUMPRODUCT((E20:R20=1)*0.3)+SUMPRODUCT((E20:R20=2)*0.7)+SUMPRODUCT((E20:R20=3)*1.5) -> 0
A21: 19 | S21: =IF(SUM(E21:R21)>0,1,0) -> 0 | T21: =IF(MAX(G21,H21,I21,J21,K21,M21,N21)>0,1,0) -> 0 | U21: =IF(MAX(E21,F21,L21,O21,Q21)>0,1,0) -> 0 | V21: =IF(P21>0,1,0) -> 0 | W21: =IF(AND(B21<>"",S21=0),1,0) -> 0 | X21: =SUMPRODUCT((E21:R21=1)*0.3)+SUMPRODUCT((E21:R21=2)*0.7)+SUMPRODUCT((E21:R21=3)*1.5) -> 0 | Y21: 대명사 중복
A22: 20 | S22: =IF(SUM(E22:R22)>0,1,0) -> 0 | T22: =IF(MAX(G22,H22,I22,J22,K22,M22,N22)>0,1,0) -> 0 | U22: =IF(MAX(E22,F22,L22,O22,Q22)>0,1,0) -> 0 | V22: =IF(P22>0,1,0) -> 0 | W22: =IF(AND(B22<>"",S22=0),1,0) -> 0 | X22: =SUMPRODUCT((E22:R22=1)*0.3)+SUMPRODUCT((E22:R22=2)*0.7)+SUMPRODUCT((E22:R22=3)*1.5) -> 0 | Y22: 어순, 불필요한 commas
A23: 21 | S23: =IF(SUM(E23:R23)>0,1,0) -> 0 | T23: =IF(MAX(G23,H23,I23,J23,K23,M23,N23)>0,1,0) -> 0 | U23: =IF(MAX(E23,F23,L23,O23,Q23)>0,1,0) -> 0 | V23: =IF(P23>0,1,0) -> 0 | W23: =IF(AND(B23<>"",S23=0),1,0) -> 0 | X23: =SUMPRODUCT((E23:R23=1)*0.3)+SUMPRODUCT((E23:R23=2)*0.7)+SUMPRODUCT((E23:R23=3)*1.5) -> 0
A24: 22 | S24: =IF(SUM(E24:R24)>0,1,0) -> 0 | T24: =IF(MAX(G24,H24,I24,J24,K24,M24,N24)>0,1,0) -> 0 | U24: =IF(MAX(E24,F24,L24,O24,Q24)>0,1,0) -> 0 | V24: =IF(P24>0,1,0) -> 0 | W24: =IF(AND(B24<>"",S24=0),1,0) -> 0 | X24: =SUMPRODUCT((E24:R24=1)*0.3)+SUMPRODUCT((E24:R24=2)*0.7)+SUMPRODUCT((E24:R24=3)*1.5) -> 0
A25: 23 | S25: =IF(SUM(E25:R25)>0,1,0) -> 0 | T25: =IF(MAX(G25,H25,I25,J25,K25,M25,N25)>0,1,0) -> 0 | U25: =IF(MAX(E25,F25,L25,O25,Q25)>0,1,0) -> 0 | V25: =IF(P25>0,1,0) -> 0 | W25: =IF(AND(B25<>"",S25=0),1,0) -> 0 | X25: =SUMPRODUCT((E25:R25=1)*0.3)+SUMPRODUCT((E25:R25=2)*0.7)+SUMPRODUCT((E25:R25=3)*1.5) -> 0
A26: 24 | S26: =IF(SUM(E26:R26)>0,1,0) -> 0 | T26: =IF(MAX(G26,H26,I26,J26,K26,M26,N26)>0,1,0) -> 0 | U26: =IF(MAX(E26,F26,L26,O26,Q26)>0,1,0) -> 0 | V26: =IF(P26>0,1,0) -> 0 | W26: =IF(AND(B26<>"",S26=0),1,0) -> 0 | X26: =SUMPRODUCT((E26:R26=1)*0.3)+SUMPRODUCT((E26:R26=2)*0.7)+SUMPRODUCT((E26:R26=3)*1.5) -> 0 | Y26: 대명사
A27: 25 | S27: =IF(SUM(E27:R27)>0,1,0) -> 0 | T27: =IF(MAX(G27,H27,I27,J27,K27,M27,N27)>0,1,0) -> 0 | U27: =IF(MAX(E27,F27,L27,O27,Q27)>0,1,0) -> 0 | V27: =IF(P27>0,1,0) -> 0 | W27: =IF(AND(B27<>"",S27=0),1,0) -> 0 | X27: =SUMPRODUCT((E27:R27=1)*0.3)+SUMPRODUCT((E27:R27=2)*0.7)+SUMPRODUCT((E27:R27=3)*1.5) -> 0 | Y27: 방금 태도치고 said 너무 평범함
A28: 26 | S28: =IF(SUM(E28:R28)>0,1,0) -> 0 | T28: =IF(MAX(G28,H28,I28,J28,K28,M28,N28)>0,1,0) -> 0 | U28: =IF(MAX(E28,F28,L28,O28,Q28)>0,1,0) -> 0 | V28: =IF(P28>0,1,0) -> 0 | W28: =IF(AND(B28<>"",S28=0),1,0) -> 0 | X28: =SUMPRODUCT((E28:R28=1)*0.3)+SUMPRODUCT((E28:R28=2)*0.7)+SUMPRODUCT((E28:R28=3)*1.5) -> 0
A29: 27 | S29: =IF(SUM(E29:R29)>0,1,0) -> 0 | T29: =IF(MAX(G29,H29,I29,J29,K29,M29,N29)>0,1,0) -> 0 | U29: =IF(MAX(E29,F29,L29,O29,Q29)>0,1,0) -> 0 | V29: =IF(P29>0,1,0) -> 0 | W29: =IF(AND(B29<>"",S29=0),1,0) -> 0 | X29: =SUMPRODUCT((E29:R29=1)*0.3)+SUMPRODUCT((E29:R29=2)*0.7)+SUMPRODUCT((E29:R29=3)*1.5) -> 0
A30: 28 | S30: =IF(SUM(E30:R30)>0,1,0) -> 0 | T30: =IF(MAX(G30,H30,I30,J30,K30,M30,N30)>0,1,0) -> 0 | U30: =IF(MAX(E30,F30,L30,O30,Q30)>0,1,0) -> 0 | V30: =IF(P30>0,1,0) -> 0 | W30: =IF(AND(B30<>"",S30=0),1,0) -> 0 | X30: =SUMPRODUCT((E30:R30=1)*0.3)+SUMPRODUCT((E30:R30=2)*0.7)+SUMPRODUCT((E30:R30=3)*1.5) -> 0
A31: 29 | S31: =IF(SUM(E31:R31)>0,1,0) -> 0 | T31: =IF(MAX(G31,H31,I31,J31,K31,M31,N31)>0,1,0) -> 0 | U31: =IF(MAX(E31,F31,L31,O31,Q31)>0,1,0) -> 0 | V31: =IF(P31>0,1,0) -> 0 | W31: =IF(AND(B31<>"",S31=0),1,0) -> 0 | X31: =SUMPRODUCT((E31:R31=1)*0.3)+SUMPRODUCT((E31:R31=2)*0.7)+SUMPRODUCT((E31:R31=3)*1.5) -> 0 | Y31: That monster is most likely to target you 등
A32: 30 | S32: =IF(SUM(E32:R32)>0,1,0) -> 0 | T32: =IF(MAX(G32,H32,I32,J32,K32,M32,N32)>0,1,0) -> 0 | U32: =IF(MAX(E32,F32,L32,O32,Q32)>0,1,0) -> 0 | V32: =IF(P32>0,1,0) -> 0 | W32: =IF(AND(B32<>"",S32=0),1,0) -> 0 | X32: =SUMPRODUCT((E32:R32=1)*0.3)+SUMPRODUCT((E32:R32=2)*0.7)+SUMPRODUCT((E32:R32=3)*1.5) -> 0
A33: 31 | S33: =IF(SUM(E33:R33)>0,1,0) -> 0 | T33: =IF(MAX(G33,H33,I33,J33,K33,M33,N33)>0,1,0) -> 0 | U33: =IF(MAX(E33,F33,L33,O33,Q33)>0,1,0) -> 0 | V33: =IF(P33>0,1,0) -> 0 | W33: =IF(AND(B33<>"",S33=0),1,0) -> 0 | X33: =SUMPRODUCT((E33:R33=1)*0.3)+SUMPRODUCT((E33:R33=2)*0.7)+SUMPRODUCT((E33:R33=3)*1.5) -> 0 | Y33: agitation 단어선정
A34: 32 | S34: =IF(SUM(E34:R34)>0,1,0) -> 0 | T34: =IF(MAX(G34,H34,I34,J34,K34,M34,N34)>0,1,0) -> 0 | U34: =IF(MAX(E34,F34,L34,O34,Q34)>0,1,0) -> 0 | V34: =IF(P34>0,1,0) -> 0 | W34: =IF(AND(B34<>"",S34=0),1,0) -> 0 | X34: =SUMPRODUCT((E34:R34=1)*0.3)+SUMPRODUCT((E34:R34=2)*0.7)+SUMPRODUCT((E34:R34=3)*1.5) -> 0
A35: 33 | S35: =IF(SUM(E35:R35)>0,1,0) -> 0 | T35: =IF(MAX(G35,H35,I35,J35,K35,M35,N35)>0,1,0) -> 0 | U35: =IF(MAX(E35,F35,L35,O35,Q35)>0,1,0) -> 0 | V35: =IF(P35>0,1,0) -> 0 | W35: =IF(AND(B35<>"",S35=0),1,0) -> 0 | X35: =SUMPRODUCT((E35:R35=1)*0.3)+SUMPRODUCT((E35:R35=2)*0.7)+SUMPRODUCT((E35:R35=3)*1.5) -> 0
A36: 34 | S36: =IF(SUM(E36:R36)>0,1,0) -> 0 | T36: =IF(MAX(G36,H36,I36,J36,K36,M36,N36)>0,1,0) -> 0 | U36: =IF(MAX(E36,F36,L36,O36,Q36)>0,1,0) -> 0 | V36: =IF(P36>0,1,0) -> 0 | W36: =IF(AND(B36<>"",S36=0),1,0) -> 0 | X36: =SUMPRODUCT((E36:R36=1)*0.3)+SUMPRODUCT((E36:R36=2)*0.7)+SUMPRODUCT((E36:R36=3)*1.5) -> 0 | Y36: 명확성부족
A37: 35 | S37: =IF(SUM(E37:R37)>0,1,0) -> 0 | T37: =IF(MAX(G37,H37,I37,J37,K37,M37,N37)>0,1,0) -> 0 | U37: =IF(MAX(E37,F37,L37,O37,Q37)>0,1,0) -> 0 | V37: =IF(P37>0,1,0) -> 0 | W37: =IF(AND(B37<>"",S37=0),1,0) -> 0 | X37: =SUMPRODUCT((E37:R37=1)*0.3)+SUMPRODUCT((E37:R37=2)*0.7)+SUMPRODUCT((E37:R37=3)*1.5) -> 0 | Y37: 라부스 대사
A38: 36 | S38: =IF(SUM(E38:R38)>0,1,0) -> 0 | T38: =IF(MAX(G38,H38,I38,J38,K38,M38,N38)>0,1,0) -> 0 | U38: =IF(MAX(E38,F38,L38,O38,Q38)>0,1,0) -> 0 | V38: =IF(P38>0,1,0) -> 0 | W38: =IF(AND(B38<>"",S38=0),1,0) -> 0 | X38: =SUMPRODUCT((E38:R38=1)*0.3)+SUMPRODUCT((E38:R38=2)*0.7)+SUMPRODUCT((E38:R38=3)*1.5) -> 0 | Y38: 위에 대사태그 추가하면 여기서 대명사 사용
A39: 37 | S39: =IF(SUM(E39:R39)>0,1,0) -> 0 | T39: =IF(MAX(G39,H39,I39,J39,K39,M39,N39)>0,1,0) -> 0 | U39: =IF(MAX(E39,F39,L39,O39,Q39)>0,1,0) -> 0 | V39: =IF(P39>0,1,0) -> 0 | W39: =IF(AND(B39<>"",S39=0),1,0) -> 0 | X39: =SUMPRODUCT((E39:R39=1)*0.3)+SUMPRODUCT((E39:R39=2)*0.7)+SUMPRODUCT((E39:R39=3)*1.5) -> 0
A40: 38 | S40: =IF(SUM(E40:R40)>0,1,0) -> 0 | T40: =IF(MAX(G40,H40,I40,J40,K40,M40,N40)>0,1,0) -> 0 | U40: =IF(MAX(E40,F40,L40,O40,Q40)>0,1,0) -> 0 | V40: =IF(P40>0,1,0) -> 0 | W40: =IF(AND(B40<>"",S40=0),1,0) -> 0 | X40: =SUMPRODUCT((E40:R40=1)*0.3)+SUMPRODUCT((E40:R40=2)*0.7)+SUMPRODUCT((E40:R40=3)*1.5) -> 0 | Y40: if the boy died, they would lose all of that 등
...

Sheet ④ 정성 평가
A1: 장면 단위 정성 평가 (각 항목 0~2점)
A2: 장면 ID | B2: 장면 설명 | C2: 대사 흐름 | D2: 속마음·이탤릭 | E2: 설정 반영 | F2: 의역 품질 | G2: 문장 구성 | H2: 검수자 만족도(0~5) | I2: 검수 시간(분) | J2: % 점수로 변환 | K2: 비고
J3: =IFERROR((C3/2*3+D3/2*2+E3/2*2+F3/2*3+G3/2*3),0) -> 0
J4: =IFERROR((C4/2*3+D4/2*2+E4/2*2+F4/2*3+G4/2*3),0) -> 0
J5: =IFERROR((C5/2*3+D5/2*2+E5/2*2+F5/2*3+G5/2*3),0) -> 0
J6: =IFERROR((C6/2*3+D6/2*2+E6/2*2+F6/2*3+G6/2*3),0) -> 0
J7: =IFERROR((C7/2*3+D7/2*2+E7/2*2+F7/2*3+G7/2*3),0) -> 0
J8: =IFERROR((C8/2*3+D8/2*2+E8/2*2+F8/2*3+G8/2*3),0) -> 0
J9: =IFERROR((C9/2*3+D9/2*2+E9/2*2+F9/2*3+G9/2*3),0) -> 0
J10: =IFERROR((C10/2*3+D10/2*2+E10/2*2+F10/2*3+G10/2*3),0) -> 0
J11: =IFERROR((C11/2*3+D11/2*2+E11/2*2+F11/2*3+G11/2*3),0) -> 0
J12: =IFERROR((C12/2*3+D12/2*2+E12/2*2+F12/2*3+G12/2*3),0) -> 0
J13: =IFERROR((C13/2*3+D13/2*2+E13/2*2+F13/2*3+G13/2*3),0) -> 0
J14: =IFERROR((C14/2*3+D14/2*2+E14/2*2+F14/2*3+G14/2*3),0) -> 0
... J32: =IFERROR((C32/2*3+D32/2*2+E32/2*2+F32/2*3+G32/2*3),0) -> 0
A34: 평균/합계 | C34: =IFERROR(AVERAGE(C3:C32),0) -> 0 | D34: =IFERROR(AVERAGE(D3:D32),0) -> 0 | E34: =IFERROR(AVERAGE(E3:E32),0) -> 0 | F34: =IFERROR(AVERAGE(F3:F32),0) -> 0 | G34: =IFERROR(AVERAGE(G3:G32),0) -> 0 | H34: =IFERROR(AVERAGE(H3:H32),0) -> 0 | I34: =IFERROR(AVERAGE(I3:I32),0) -> 0 | J34: =IFERROR(AVERAGE(J3:J32),0) -> 0

Sheet ⑤ 결과 대시보드
A1: 결과 대시보드
A4: 프롬프트 버전 | B4: V1 | C4: 평가 일자 | D4: 46181
A6: 정량 지표
A7: 지표 | B7: 기준 | C7: 실제 값 | D7: 판정 | E7: 비고
A8: 전체 수정률 (%) | B8: ≤ 50 | C8: =IFERROR(SUM('③ 평가 입력'!S3:S202)/COUNTA('③ 평가 입력'!B3:B202)*100,0) -> 0 | D8: =IF(C8="","",IF(C8<=50,"통과","미달")) -> 통과
A9: 의미 오류 수정률 (%) | B9: ≤ 20 | C9: =IFERROR(SUM('③ 평가 입력'!T3:T202)/COUNTA('③ 평가 입력'!B3:B202)*100,0) -> 0 | D9: =IF(C9="","",IF(C9<=20,"통과","미달")) -> 통과
A10: 형식 오류 수정률 (%) | B10: ≤ 15 | C10: =IFERROR(SUM('③ 평가 입력'!U3:U202)/COUNTA('③ 평가 입력'!B3:B202)*100,0) -> 0 | D10: =IF(C10="","",IF(C10<=15,"통과","미달")) -> 통과
A11: 흐름 오류 발생률 (%) | B11: ≤ 10 | C11: =IFERROR(SUM('③ 평가 입력'!V3:V202)/COUNTA('③ 평가 입력'!B3:B202)*100,0) -> 0 | D11: =IF(C11="","",IF(C11<=10,"통과","미달")) -> 통과
A12: 수정 없이 넘긴 비율 (%) | B12: ≥ 30 | C12: =IFERROR(SUM('③ 평가 입력'!W3:W202)/COUNTA('③ 평가 입력'!B3:B202)*100,0) -> 0 | D12: =IF(C12="","",IF(C12>=30,"통과","미달")) -> 미달
A14: 카테고리별 발생률 (강도≥1 문장 비율)
A15: # | B15: 카테고리 | C15: 발생 건수 | D15: 발생률 (%) | E15: 비고
A16: 1 | B16: 오타·표기 | C16: =COUNTIF('③ 평가 입력'!E3:E202,">=1") -> 0 | D16: =IFERROR(C16/COUNTA('③ 평가 입력'!B3:B202)*100,0) -> 0
A17: 2 | B17: 문법·구조 | C17: =COUNTIF('③ 평가 입력'!F3:F202,">=1") -> 0 | D17: =IFERROR(C17/COUNTA('③ 평가 입력'!B3:B202)*100,0) -> 0
A18: 3 | B18: 오역 | C18: =COUNTIF('③ 평가 입력'!G3:G202,">=1") -> 0 | D18: =IFERROR(C18/COUNTA('③ 평가 입력'!B3:B202)*100,0) -> 0
A19: 4 | B19: 톤·감정 | C19: =COUNTIF('③ 평가 입력'!H3:H202,">=1") -> 0 | D19: =IFERROR(C19/COUNTA('③ 평가 입력'!B3:B202)*100,0) -> 0
A20: 5 | B20: 호칭·경칭 | C20: =COUNTIF('③ 평가 입력'!I3:I202,">=1") -> 0 | D20: =IFERROR(C20/COUNTA('③ 평가 입력'!B3:B202)*100,0) -> 0
A21: 6 | B21: 직역체 | C21: =COUNTIF('③ 평가 입력'!J3:J202,">=1") -> 0 | D21: =IFERROR(C21/COUNTA('③ 평가 입력'!B3:B202)*100,0) -> 0
A22: 7 | B22: AI 과잉표현 | C22: =COUNTIF('③ 평가 입력'!K3:K202,">=1") -> 0 | D22: =IFERROR(C22/COUNTA('③ 평가 입력'!B3:B202)*100,0) -> 0
A23: 8 | B23: 대사 태그 | C23: =COUNTIF('③ 평가 입력'!L3:L202,">=1") -> 0 | D23: =IFERROR(C23/COUNTA('③ 평가 입력'!B3:B202)*100,0) -> 0
A24: 9 | B24: 비유·관용어 | C24: =COUNTIF('③ 평가 입력'!M3:M202,">=1") -> 0 | D24: =IFERROR(C24/COUNTA('③ 평가 입력'!B3:B202)*100,0) -> 0
A25: 10 | B25: 설정·세계관 | C25: =COUNTIF('③ 평가 입력'!N3:N202,">=1") -> 0 | D25: =IFERROR(C25/COUNTA('③ 평가 입력'!B3:B202)*100,0) -> 0
A26: 11 | B26: 스타일·표기 | C26: =COUNTIF('③ 평가 입력'!O3:O202,">=1") -> 0 | D26: =IFERROR(C26/COUNTA('③ 평가 입력'!B3:B202)*100,0) -> 0
A27: 12 | B27: 흐름·중복 | C27: =COUNTIF('③ 평가 입력'!P3:P202,">=1") -> 0 | D27: =IFERROR(C27/COUNTA('③ 평가 입력'!B3:B202)*100,0) -> 0
A28: 13 | B28: 서술 규칙 | C28: =COUNTIF('③ 평가 입력'!Q3:Q202,">=1") -> 0 | D28: =IFERROR(C28/COUNTA('③ 평가 입력'!B3:B202)*100,0) -> 0
A29: 14 | B29: 기타 | C29: =COUNTIF('③ 평가 입력'!R3:R202,">=1") -> 0 | D29: =IFERROR(C29/COUNTA('③ 평가 입력'!B3:B202)*100,0) -> 0
A31: 정성 평가 가산점
A32: 평균 % 점수 (가산점) | B32: ='④ 정성 평가'!J34 -> 0 | C32: 실질 수정률 (%) | D32: =MAX(0,C8-B32) -> 0
A34: 최종 판정
A35: 판정 | B35: =IF(COUNTIF(D8:D12,"미달")=0,"✅ 통과",IF(AND(COUNTIF(D8:D12,"미달")=1,D32<=50,C9>20=FALSE()),"⚠ 조건부 통과",IF(OR(COUNTIF(D8:D12,"미달")>=2,C9>20),"❌ 실패","⚠ 조건부 통과"))) -> ⚠ 조건부 통과

Sheet ⑥ 버전 비교
A1: 버전 비교 (v1 기준값 vs v1.x 개선안)
A2: 각 버전의 ⑤ 결과 대시보드 수치를 수동으로 옮겨 적습니다. 변화량(현재−v1)이 2%p 이상 나빠지면 "나빠짐" 표시가 자동으로 나타납니다.
A4: 지표 | B4: v1 (기준값) | C4: v1.x (현재) | D4: 변화량 (현재−v1) | E4: 방향 | F4: 나빠짐 표시 | G4: v2 기준 | H4: 판정
A5: 총 수정률 (%) | B5: =IFERROR(SUM('③ 평가 입력'!#REF!)/COUNTA('③ 평가 입력'!#REF!)*100,0) -> 0 | D5: =IFERROR(C5-B5,"") -> 0 | E5: =IF(D5="","",IF(D5<0,"개선",IF(D5>0,"악화","유지"))) -> 유지 | F5: =IF(D5="","",IF(D5>=2,"⚠ 나빠짐","")) | G5: ≤ 50 | H5: =IF(C5="","",IF(C5<=VALUE(SUBSTITUTE(G5,"≤ ","")),"통과","미달"))
A6: 의미 오류 수정률 (%) | B6: =IFERROR(SUM('③ 평가 입력'!#REF!)/COUNTA('③ 평가 입력'!#REF!)*100,0) -> 0 | D6: =IFERROR(C6-B6,"") -> 0 | E6: =IF(D6="","",IF(D6<0,"개선",IF(D6>0,"악화","유지"))) -> 유지 | F6: =IF(D6="","",IF(D6>=2,"⚠ 나빠짐","")) | G6: ≤ 20 | H6: =IF(C6="","",IF(C6<=VALUE(SUBSTITUTE(G6,"≤ ","")),"통과","미달"))
A7: 형식 오류 수정률 (%) | B7: =IFERROR(SUM('③ 평가 입력'!#REF!)/COUNTA('③ 평가 입력'!#REF!)*100,0) -> 0 | D7: =IFERROR(C7-B7,"") -> 0 | E7: =IF(D7="","",IF(D7<0,"개선",IF(D7>0,"악화","유지"))) -> 유지 | F7: =IF(D7="","",IF(D7>=2,"⚠ 나빠짐","")) | G7: ≤ 15 | H7: =IF(C7="","",IF(C7<=VALUE(SUBSTITUTE(G7,"≤ ","")),"통과","미달"))
A8: 흐름 오류 발생률 (%) | B8: =IFERROR(SUM('③ 평가 입력'!#REF!)/COUNTA('③ 평가 입력'!#REF!)*100,0) -> 0 | D8: =IFERROR(C8-B8,"") -> 0 | E8: =IF(D8="","",IF(D8<0,"개선",IF(D8>0,"악화","유지"))) -> 유지 | F8: =IF(D8="","",IF(D8>=2,"⚠ 나빠짐","")) | G8: ≤ 10 | H8: =IF(C8="","",IF(C8<=VALUE(SUBSTITUTE(G8,"≤ ","")),"통과","미달"))
A9: 수정 없이 넘긴 비율 (%) | B9: =IFERROR(SUM('③ 평가 입력'!#REF!)/COUNTA('③ 평가 입력'!#REF!)*100,0) -> 0 | D9: =IFERROR(C9-B9,"") -> 0 | E9: =IF(D9="","",IF(D9>0,"개선",IF(D9<0,"악화","유지"))) -> 유지 | F9: =IF(D9="","",IF(D9<=-2,"⚠ 나빠짐","")) | G9: ≥ 30 | H9: =IF(C9="","",IF(C9>=VALUE(SUBSTITUTE(G9,"≥ ","")),"통과","미달"))
A11: 카테고리별 발생률 비교 (%)
A12: # | B12: 카테고리 | C12: v1 | D12: v1.x | E12: 변화량 | F12: 방향 | G12: 나빠짐 | H12: 비고
A13: 1 | B13: 오타·표기 | C13: =IFERROR(B13/COUNTA('③ 평가 입력'!#REF!)*100,0) -> 0 | E13: =IFERROR(D13-C13,"") -> 0 | F13: =IF(E13="","",IF(E13<0,"개선",IF(E13>0,"악화","유지"))) -> 유지 | G13: =IF(E13="","",IF(E13>=2,"⚠ 나빠짐",""))
A14: 2 | B14: 문법·구조 | C14: =IFERROR(B14/COUNTA('③ 평가 입력'!#REF!)*100,0) -> 0 | E14: =IFERROR(D14-C14,"") -> 0 | F14: =IF(E14="","",IF(E14<0,"개선",IF(E14>0,"악화","유지"))) -> 유지 | G14: =IF(E14="","",IF(E14>=2,"⚠ 나빠짐",""))
A15: 3 | B15: 오역 | C15: =IFERROR(B15/COUNTA('③ 평가 입력'!#REF!)*100,0) -> 0 | E15: =IFERROR(D15-C15,"") -> 0 | F15: =IF(E15="","",IF(E15<0,"개선",IF(E15>0,"악화","유지"))) -> 유지 | G15: =IF(E15="","",IF(E15>=2,"⚠ 나빠짐",""))
A16: 4 | B16: 톤·감정 | C16: =IFERROR(B16/COUNTA('③ 평가 입력'!#REF!)*100,0) -> 0 | E16: =IFERROR(D16-C16,"") -> 0 | F16: =IF(E16="","",IF(E16<0,"개선",IF(E16>0,"악화","유지"))) -> 유지 | G16: =IF(E16="","",IF(E16>=2,"⚠ 나빠짐",""))
A17: 5 | B17: 호칭·경칭 | C17: =IFERROR(B17/COUNTA('③ 평가 입력'!#REF!)*100,0) -> 0 | E17: =IFERROR(D17-C17,"") -> 0 | F17: =IF(E17="","",IF(E17<0,"개선",IF(E17>0,"악화","유지"))) -> 유지 | G17: =IF(E17="","",IF(E17>=2,"⚠ 나빠짐",""))
A18: 6 | B18: 직역체 | C18: =IFERROR(B18/COUNTA('③ 평가 입력'!#REF!)*100,0) -> 0 | E18: =IFERROR(D18-C18,"") -> 0 | F18: =IF(E18="","",IF(E18<0,"개선",IF(E18>0,"악화","유지"))) -> 유지 | G18: =IF(E18="","",IF(E18>=2,"⚠ 나빠짐",""))
A19: 7 | B19: AI 과잉표현 | C19: =IFERROR(B19/COUNTA('③ 평가 입력'!#REF!)*100,0) -> 0 | E19: =IFERROR(D19-C19,"") -> 0 | F19: =IF(E19="","",IF(E19<0,"개선",IF(E19>0,"악화","유지"))) -> 유지 | G19: =IF(E19="","",IF(E19>=2,"⚠ 나빠짐",""))
A20: 8 | B20: 대사 태그 | C20: =IFERROR(B20/COUNTA('③ 평가 입력'!#REF!)*100,0) -> 0 | E20: =IFERROR(D20-C20,"") -> 0 | F20: =IF(E20="","",IF(E20<0,"개선",IF(E20>0,"악화","유지"))) -> 유지 | G20: =IF(E20="","",IF(E20>=2,"⚠ 나빠짐",""))
A21: 9 | B21: 비유·관용어 | C21: =IFERROR(B21/COUNTA('③ 평가 입력'!#REF!)*100,0) -> 0 | E21: =IFERROR(D21-C21,"") -> 0 | F21: =IF(E21="","",IF(E21<0,"개선",IF(E21>0,"악화","유지"))) -> 유지 | G21: =IF(E21="","",IF(E21>=2,"⚠ 나빠짐",""))
A22: 10 | B22: 설정·세계관 | C22: =IFERROR(B22/COUNTA('③ 평가 입력'!#REF!)*100,0) -> 0 | E22: =IFERROR(D22-C22,"") -> 0 | F22: =IF(E22="","",IF(E22<0,"개선",IF(E22>0,"악화","유지"))) -> 유지 | G22: =IF(E22="","",IF(E22>=2,"⚠ 나빠짐",""))
A23: 11 | B23: 스타일·표기 | C23: =IFERROR(B23/COUNTA('③ 평가 입력'!#REF!)*100,0) -> 0 | E23: =IFERROR(D23-C23,"") -> 0 | F23: =IF(E23="","",IF(E23<0,"개선",IF(E23>0,"악화","유지"))) -> 유지 | G23: =IF(E23="","",IF(E23>=2,"⚠ 나빠짐",""))
A24: 12 | B24: 흐름·중복 | C24: =IFERROR(B24/COUNTA('③ 평가 입력'!#REF!)*100,0) -> 0 | E24: =IFERROR(D24-C24,"") -> 0 | F24: =IF(E24="","",IF(E24<0,"개선",IF(E24>0,"악화","유지"))) -> 유지 | G24: =IF(E24="","",IF(E24>=2,"⚠ 나빠짐",""))
... A26: 14 | B26: 기타 | C26: =IFERROR(B26/COUNTA('③ 평가 입력'!#REF!)*100,0) -> 0 | E26: =IFERROR(D26-C26,"") -> 0 | F26: =IF(E26="","",IF(E26<0,"개선",IF(E26>0,"악화","유지"))) -> 유지 | G26: =IF(E26="","",IF(E26>=2,"⚠ 나빠짐",""))

Sheet ⑦ 기타 사례 누적
A1: "기타" 분류 사례 누적 (신규 카테고리 후보 발굴용)
A3: 일자 | B3: 버전 | C3: 원문 | D3: MT본 | E3: 문제 패턴 요약 | F3: 분류 후보

Sheet ⑧ 평가자 일치율
A1: 평가자 일치율 측정 (본 평가 진입 전 필수)
A2: 평가자 2명이 동일한 30문장을 따로 평가한 결과를 입력하면 일치율이 자동 계산됩니다. 카테고리 일치율 70% 이상이 본 평가 진입 조건입니다.
A4: 평가자 A 이름 | C4: 평가자 B 이름 | E4: 측정 일자
A6: 문장 # | B6: 원문 | C6: MT본 | D6: 평가자 A | F6: 평가자 B | H6: 카테고리 일치 | I6: 강도 일치 | J6: 어긋난 사유
D7: 카테고리 | E7: 강도 | F7: 카테고리 | G7: 강도
A8: 1
A9: 2
A10: 3 | K10: 동의함
A11: 4
A12: 5
A13: 6 | K13: 이해함
A14: 7 | K14: 이해함
A15: 8
A16: 9
A17: 10
A18: 11
A19: 12 | K19: 동의함
A20: 13
A21: 14
A22: 15
A23: 16
A24: 17
A25: 18 | K25: 동의함
A26: 19
A27: 20
A28: 21 | K28: 동의함
A29: 22 | K29: 동의함
A30: 23 | K30: 이해함
A31: 24
A32: 25
A33: 26
A34: 27
A35: 28
A36: 29
A37: 30
A38: 31
A39: 32
A40: 33
A41: 34
A42: 35
...

Sheet ⑨ 본 평가 비교
A1: 본 평가 결과 비교 (평가자 A · B 결과 자동 비교 및 합산)
A3: 문장 # | B3: 원문 | C3: MT본 | D3: 검수본 | E3: 평가자 A — 카테고리별 강도 (0~3) | S3: 평가자 B — 카테고리별 강도 (0~3) | AG3: 카테고리 일치 | AH3: 강도 일치 | AI3: 합의 권장 강도 | AJ3: 비고
E4: 1.오타 | F4: 2.문법 | G4: 3.오역 | H4: 4.톤감정 | I4: 5.호칭 | J4: 6.직역 | K4: 7.AI표현 | L4: 8.대사태그 | M4: 9.비유관용 | N4: 10.설정 | O4: 11.스타일 | P4: 12.흐름중복 | Q4: 13.서술규칙 | R4: 14.기타 | S4: 1.오타 | T4: 2.문법 | U4: 3.오역 | V4: 4.톤감정 | W4: 5.호칭 | X4: 6.직역 | Y4: 7.AI표현 | Z4: 8.대사태그 | AA4: 9.비유관용 | AB4: 10.설정 | AC4: 11.스타일 | AD4: 12.흐름중복 | AE4: 13.서술규칙 | AF4: 14.기타
A5: 1 | AG5: =IF(AND(B5="",E5="",S5=""),"",IF(SUMPRODUCT(((E5:R5>=1)<>(S5:AF5>=1))*1)=0,"○","✗")) | AH5: =IF(AG5="","",IF(AG5="✗","✗",IF(SUMPRODUCT((E5:R5<>S5:AF5)*1)=0,"○","✗"))) | AI5: =IF(AND(SUM(E5:R5)=0,SUM(S5:AF5)=0),0,(SUM(E5:R5)+SUM(S5:AF5))/2) -> 0
A6: 2 | AG6: =IF(AND(B6="",E6="",S6=""),"",IF(SUMPRODUCT(((E6:R6>=1)<>(S6:AF6>=1))*1)=0,"○","✗")) | AH6: =IF(AG6="","",IF(AG6="✗","✗",IF(SUMPRODUCT((E6:R6<>S6:AF6)*1)=0,"○","✗"))) | AI6: =IF(AND(SUM(E6:R6)=0,SUM(S6:AF6)=0),0,(SUM(E6:R6)+SUM(S6:AF6))/2) -> 0
A7: 3 | AG7: =IF(AND(B7="",E7="",S7=""),"",IF(SUMPRODUCT(((E7:R7>=1)<>(S7:AF7>=1))*1)=0,"○","✗")) | AH7: =IF(AG7="","",IF(AG7="✗","✗",IF(SUMPRODUCT((E7:R7<>S7:AF7)*1)=0,"○","✗"))) | AI7: =IF(AND(SUM(E7:R7)=0,SUM(S7:AF7)=0),0,(SUM(E7:R7)+SUM(S7:AF7))/2) -> 0
A8: 4 | AG8: =IF(AND(B8="",E8="",S8=""),"",IF(SUMPRODUCT(((E8:R8>=1)<>(S8:AF8>=1))*1)=0,"○","✗")) | AH8: =IF(AG8="","",IF(AG8="✗","✗",IF(SUMPRODUCT((E8:R8<>S8:AF8)*1)=0,"○","✗"))) | AI8: =IF(AND(SUM(E8:R8)=0,SUM(S8:AF8)=0),0,(SUM(E8:R8)+SUM(S8:AF8))/2) -> 0
A9: 5 | AG9: =IF(AND(B9="",E9="",S9=""),"",IF(SUMPRODUCT(((E9:R9>=1)<>(S9:AF9>=1))*1)=0,"○","✗")) | AH9: =IF(AG9="","",IF(AG9="✗","✗",IF(SUMPRODUCT((E9:R9<>S9:AF9)*1)=0,"○","✗"))) | AI9: =IF(AND(SUM(E9:R9)=0,SUM(S9:AF9)=0),0,(SUM(E9:R9)+SUM(S9:AF9))/2) -> 0
A10: 6 | AG10: =IF(AND(B10="",E10="",S10=""),"",IF(SUMPRODUCT(((E10:R10>=1)<>(S10:AF10>=1))*1)=0,"○","✗")) | AH10: =IF(AG10="","",IF(AG10="✗","✗",IF(SUMPRODUCT((E10:R10<>S10:AF10)*1)=0,"○","✗"))) | AI10: =IF(AND(SUM(E10:R10)=0,SUM(S10:AF10)=0),0,(SUM(E10:R10)+SUM(S10:AF10))/2) -> 0
A11: 7 | AG11: =IF(AND(B11="",E11="",S11=""),"",IF(SUMPRODUCT(((E11:R11>=1)<>(S11:AF11>=1))*1)=0,"○","✗")) | AH11: =IF(AG11="","",IF(AG11="✗","✗",IF(SUMPRODUCT((E11:R11<>S11:AF11)*1)=0,"○","✗"))) | AI11: =IF(AND(SUM(E11:R11)=0,SUM(S11:AF11)=0),0,(SUM(E11:R11)+SUM(S11:AF11))/2) -> 0
A12: 8 | AG12: =IF(AND(B12="",E12="",S12=""),"",IF(SUMPRODUCT(((E12:R12>=1)<>(S12:AF12>=1))*1)=0,"○","✗")) | AH12: =IF(AG12="","",IF(AG12="✗","✗",IF(SUMPRODUCT((E12:R12<>S12:AF12)*1)=0,"○","✗"))) | AI12: =IF(AND(SUM(E12:R12)=0,SUM(S12:AF12)=0),0,(SUM(E12:R12)+SUM(S12:AF12))/2) -> 0
A13: 9 | AG13: =IF(AND(B13="",E13="",S13=""),"",IF(SUMPRODUCT(((E13:R13>=1)<>(S13:AF13>=1))*1)=0,"○","✗")) | AH13: =IF(AG13="","",IF(AG13="✗","✗",IF(SUMPRODUCT((E13:R13<>S13:AF13)*1)=0,"○","✗"))) | AI13: =IF(AND(SUM(E13:R13)=0,SUM(S13:AF13)=0),0,(SUM(E13:R13)+SUM(S13:AF13))/2) -> 0
A14: 10 | AG14: =IF(AND(B14="",E14="",S14=""),"",IF(SUMPRODUCT(((E14:R14>=1)<>(S14:AF14>=1))*1)=0,"○","✗")) | AH14: =IF(AG14="","",IF(AG14="✗","✗",IF(SUMPRODUCT((E14:R14<>S14:AF14)*1)=0,"○","✗"))) | AI14: =IF(AND(SUM(E14:R14)=0,SUM(S14:AF14)=0),0,(SUM(E14:R14)+SUM(S14:AF14))/2) -> 0
A15: 11 | AG15: =IF(AND(B15="",E15="",S15=""),"",IF(SUMPRODUCT(((E15:R15>=1)<>(S15:AF15>=1))*1)=0,"○","✗")) | AH15: =IF(AG15="","",IF(AG15="✗","✗",IF(SUMPRODUCT((E15:R15<>S15:AF15)*1)=0,"○","✗"))) | AI15: =IF(AND(SUM(E15:R15)=0,SUM(S15:AF15)=0),0,(SUM(E15:R15)+SUM(S15:AF15))/2) -> 0
A16: 12 | AG16: =IF(AND(B16="",E16="",S16=""),"",IF(SUMPRODUCT(((E16:R16>=1)<>(S16:AF16>=1))*1)=0,"○","✗")) | AH16: =IF(AG16="","",IF(AG16="✗","✗",IF(SUMPRODUCT((E16:R16<>S16:AF16)*1)=0,"○","✗"))) | AI16: =IF(AND(SUM(E16:R16)=0,SUM(S16:AF16)=0),0,(SUM(E16:R16)+SUM(S16:AF16))/2) -> 0
... A351: 347 | AG351: =IF(AND(B351="",E351="",S351=""),"",IF(SUMPRODUCT(((E351:R351>=1)<>(S351:AF351>=1))*1)=0,"○","✗")) | AH351: =IF(AG351="","",IF(AG351="✗","✗",IF(SUMPRODUCT((E351:R351<>S351:AF351)*1)=0,"○","✗"))) | AI351: =IF(AND(SUM(E351:R351)=0,SUM(S351:AF351)=0),0,(SUM(E351:R351)+SUM(S351:AF351))/2) -> 0
A353: 본 평가 일치율 결과
A354: 평가 완료 문장 수 | B354: 600 권장 | C354: =COUNTIF(AG5:AG351,"○")+COUNTIF(AG5:AG351,"✗") -> 0 | D354: 참고
A355: 카테고리 일치율 (%) | B355: ≥ 70% | C355: =IFERROR(COUNTIF(AG5:AG351,"○")/(COUNTIF(AG5:AG351,"○")+COUNTIF(AG5:AG351,"✗"))*100,0) -> 0 | D355: =IF(C355="","",IF(C355>=70,"✅ 1차 게이트 통과",IF(C355>=50,"⚠ 데이터 신뢰도 부족","❌ 데이터 무효"))) -> ❌ 데이터 무효
A356: 강도 일치율 (%) | B356: ≥ 60% | C356: =IFERROR(COUNTIF(AH5:AH351,"○")/(COUNTIF(AH5:AH351,"○")+COUNTIF(AH5:AH351,"✗"))*100,0) -> 0 | D356: =IF(C356="","",IF(C356>=60,"✅ 충분","⚠ 강도 합의 부족")) -> ⚠ 강도 합의 부족
A357: 합의 필요 문장 수 | B357: 참고 | C357: =COUNTIF(AG5:AG351,"✗") -> 0 | D357: 회의 대상
