Workbook

Sheet ① 안내
A1: 한→일 소설 MT 평가표 v2
A2: v1 이후 프롬프트 개발·개선을 위한 버전별 변화 추적 + 개선 우선순위 도출용 평가표
A4: 시트 구성
A5: ① 안내 | B5: 본 시트. 평가 기준·운영 방식 요약
A6: ② 카테고리 정의 | B6: 13개 카테고리의 정의·예시·강도 점수 기준
A7: ③ 평가 입력 | B7: 문장 단위 평가 입력 시트(메인 작업 시트)
A8: ④ 정성 평가 | B8: 장면 단위 정성 7항목 평가
A9: ⑤ 결과 대시보드 | B9: 정량 지표·카테고리별 발생률·통과 여부 자동 산출
A10: ⑥ 버전 비교 | B10: v1과 v1.x의 변화량·나빠진 항목 비교
A11: ⑦ 기타 사례 누적 | B11: "기타" 분류 사례 모아 신규 카테고리화 검토
A12: ⑧ 평가자 일치율 | B12: 본 평가 전 평가자 2~3명의 분류 일치율 측정 및 본 평가 진입 가능 여부 자동 판정
A13: ⑨ 본 평가 비교 | B13: 두 평가자 결과를 붙여넣어 본 평가 중 일치율 측정 + 합의 권장값 자동 산출
A15: 평가 단계
A16: 1. 사전 준비 | B16: 평가용 원문 셋 고정. 동일 셋을 v1·v1.x에 적용해야 비교 가능. 최소 3작품 × 100~200문장 권장.
A17: 2. 평가자 기준 맞추기 | B17: 평가자 2명 이상이 동일 30문장을 따로 평가한 뒤, 같은 카테고리로 분류한 비율을 확인합니다. 70% 이상 일치하면 본 평가 진입, 미만이면 카테고리 정의를 다시 합의합니다.
A18: 3. 본 평가 | B18: ③ 평가 입력 시트에 문장 단위 강도(0~3) 입력. 한 문장당 최대 1~2개 카테고리.
A19: 4. 정성 평가 | B19: ④ 정성 평가 시트에 장면 단위로 7항목 0~2점으로 입력.
A20: 5. 집계·비교 | B20: ⑤ 대시보드 자동 산출 → ⑥ 버전 비교에서 v1 대비 변화량·나빠진 항목 점검.
A21: 6. 판정 | B21: 통과 / 조건부 통과 / 실패 + 개선 우선순위 카테고리 도출.
A23: 정량 기준 (v2 강화 기준)
A24: 총 수정률 | B24: ≤ 45% (v1: 50%) — 카테고리 1~13 전체 (강도 ≥1)
A25: 의미 오류 수정률 | B25: ≤ 17% (v1: 20%) — 카테고리 3·5·6·7·8·9·12
A26: 형식 오류 수정률 | B26: ≤ 12% (v1: 15%) — 카테고리 1·2·4·10
A27: 시제 오류 발생률 | B27: ≤ 8% (v1: 10%) — 카테고리 11
A28: 수정 없이 넘긴 문장 비율 | B28: ≥ 35% (v1: 30%) — 카테고리 1~13 모두 강도 0인 문장
A29: 기타 (13번) | B29: 총 수정률에는 포함, 의미·형식·시제 어느 그룹에도 속하지 않음 (분류 후보 발굴용)
A30: 나빠짐 표시 (신규) | B30: v1 대비 어떤 카테고리든 발생률이 2%p 이상 늘어나면 표시
A31: 샘플 안정성 (신규)
A33: 정성 가산점 (장면 단위)
A34: 대사 흐름 자연스러움 | B34: 0~2점 → % 점수로 변환 시 +3% 가능
A35: 속마음·이탤릭 구분 | B35: 0~2점 → % 점수로 변환 시 +2% 가능
A36: 설정집 반영 정확도 | B36: 0~2점 → % 점수로 변환 시 +2% 가능
A37: 직역 탈피·의역 품질 | B37: 0~2점 → % 점수로 변환 시 +3% 가능
A38: 문장 구성 능력 | B38: 0~2점 → % 점수로 변환 시 +3% 가능
A39: 검수자 만족도 | B39: 0~5점 (참고용)
A40: 검수 시간 단축률
A42: 한→일 번역 언어쌍 특화 포인트
A43: 문체 종결형 | B43: だ・である체 vs です・ます체. 지문은 보통 だ체, 대사는 캐릭터별. MT가 한 톤으로 미는 경향.
A44: 경어 체계 | B44: 尊敬語·謙譲語·丁寧語 3중 체계. 한국어 어미 존댓말과 매핑이 1:1이 아님.
A45: 1·2인칭 | B45: 私·僕·俺·あたし / あなた·君·お前·貴様 등 캐릭터 성격을 직접 드러냄.
...

Sheet ② 카테고리 정의
A1: # | B1: 카테고리 | C1: 정의 | D1: 한→일 특화 포인트 | E1: 강도 1 예시 | F1: 강도 2 예시 | G1: 강도 3 예시 | H1: 집계 그룹
A2: 1 | B2: 오타·표기 오류 | C2: 오탈자, 띄어쓰기, 한자 변환 오류, 송가나(送り仮名) 오류 | D2: 한자/히라가나/가타카나 변환 미스, 가타카나 외래어 표기 오류 | E2: 경미한 송가나 누락 | F2: 한자 변환 오류 명확 | G2: 의미 전달 실패하는 표기 오류 | H2: 형식 오류
A3: 2 | B3: 문법 오류 | C3: 조사 오용, 활용 어미 오류, 어순 부자연 | D3: は/が/を/に 조사 오용, 활용 어미(~ている/てある) 오류 | E3: 조사 1개 어색 | F3: 문법 명백한 오류 | G3: 문장 의미 파악 어려움 | H3: 형식 오류
A4: 3 | B4: 오역 | C4: 의미 왜곡, 발화자 혼동, 중요 내용 누락 | D4: 한국어 원문 의미를 일본어로 잘못 옮김 | E4: 뉘앙스 미세 차이 | F4: 의미 일부 왜곡 | G4: 핵심 의미 완전 왜곡, 플롯 영향 | H4: 의미 오류
A5: 4 | B5: 문체 종결형 오류 | C5: だ·である체 vs です·ます체 혼용, 지문/대사 톤 불일치 | D5: 소설 지문은 보통 だ·である체. MT가 한 톤으로 밀어버리는 경우 빈번 | E5: 경미한 톤 흔들림 | F5: 지문/대사 톤 불일치 명확 | G5: 작품 전체 톤 붕괴 | H5: 형식 오류
A6: 5 | B6: 경어·호칭 오류 | C6: 尊敬語·謙譲語·丁寧語 오용, 호칭 접미사(さん·様·ちゃん 등) 부적절 | D6: 한국어 존댓말 어미를 단순 です·ます로만 처리, 동사 자체 변형 누락(言う→おっしゃる) | E6: 경어 단계 미세 부적절 | F6: 경어 종류 잘못 선택 | G6: 캐릭터 관계·계급 붕괴 | H6: 의미 오류
A7: 6 | B7: 1·2인칭 선택 오류 | C7: 私·僕·俺·あたし / あなた·君·お前 등 캐릭터 성격에 안 맞는 인칭 | D7: 한국어 "나/너"는 단순하나 일본어는 캐릭터 성격을 직접 드러냄 | E7: 인칭 살짝 어색 | F7: 캐릭터 성격과 안 맞는 인칭 | G7: 인칭 일관성 붕괴 또는 정체성 왜곡 | H7: 의미 오류
A8: 7 | B8: 오노마토페 처리 미흡 | C8: 한국어 의성·의태어를 일본어 オノマトペ로 살리지 못하고 평이하게 처리 | D8: "두근두근"→ドキドキ, "후다닥"→バタバタ 등 살리는 능력. MT는 동사로 풀어버리는 경향 | E8: 오노마토페 선택 살짝 어색 | F8: 오노마토페 누락하고 평이하게 처리 | G8: 장면 분위기 완전히 붕괴 | H8: 의미 오류
A9: 8 | B9: 설정·세계관 위반 | C9: 용어집(TB) 용어 미반영(고유명사·인명·지명), 시대·장르 부적합 어휘 | D9: 판타지·이세계물 고유명사 표기 통일, 시대물에서 현대어 사용 금지 | E9: 용어집 용어 미세 불일치 | F9: 용어집 용어 명확히 누락 | G9: 세계관 핵심 설정 위반 | H9: 의미 오류
A10: 9 | B10: 직역체·부자연스러움 | C10: 한국어 구조 잔존, 일본어로서 어색. 윤문 부족 | D10: 한국어 어순·구조를 그대로 옮겨 일본어로서 어색한 문장 | E10: 약간 어색한 표현 | F10: 직역 티가 명확 | G10: 일본어 화자가 거의 안 쓰는 문장 | H10: 의미 오류
A11: 10 | B11: 스타일 가이드·표기 | C11: 문장부호(「」『』), 가타카나 선택, 루비(후리가나), 줄바꿈, 숫자 표기 | D11: 대사 부호 「」, 책 제목 『』, 가타카나/한자 선택, 루비 처리 | E11: 경미한 표기 흔들림 | F11: 가이드 명백 위반 | G11: 가독성 심각 저하 | H11: 형식 오류
A12: 11 | B12: 시제·시점 오류 | C12: 시제 일관성 부족, 시점 전환 부자연, 사건 순서 어긋남 | D12: 한·일 시제 표현 차이(~ていた vs 했었다), 장면 내 시제 일관성 | E12: 한 문장 시제 흔들림 | F12: 문단 내 시제 일관성 부족 | G12: 시점·사건 순서 붕괴 | H12: 시제 오류
... A14: 13 | B14: 기타 | C14: 위 항목에 포함되지 않으나 번역 품질에 영향 | D14: 신규 카테고리 후보 누적용. ⑦ 시트에 사례 기록 | E14: 경미한 기타 문제 | F14: 명확한 기타 문제 | G14: 심각한 기타 문제 | H14: 기타
A17: 강도 점수 기준
A18: 점수 | B18: 의미 | C18: 판정 기준 | D18: 집계 가중치
A19: 0 | B19: 문제 없음 | C19: 수정 불필요 | D19: 0.0
A20: 1 | B20: 경미 | C20: 다듬으면 좋으나 의미 전달 OK | D20: 0.3
A21: 2 | B21: 보통 | C21: 검수자가 명확히 수정해야 함 | D21: 0.7
A22: 3 | B22: 치명 | C22: 독자 이해 실패, 캐릭터 붕괴 등 | D22: 1.5

Sheet ③ 평가 입력
A1: 작품·문장 번호 | B1: 원문 (한국어) | C1: 사람 번역본 (참고) | D1: MT본 (일본어) | E1: 검수본 (수정 결과) | F1: 카테고리별 강도 (0~3) | S1: 문장 단위 집계 | Y1: 비고
F2: 1.오타 | G2: 2.문법 | H2: 3.오역 | I2: 4.문체 | J2: 5.경어 | K2: 6.인칭 | L2: 7.오노마 | M2: 8.설정 | N2: 9.직역 | O2: 10.스타일 | P2: 11.시제 | Q2: 12.일관 | R2: 13.기타 | S2: 수정여부 | T2: 의미오류 | U2: 형식오류 | V2: 시제오류 | W2: 미수정 | X2: 강도합
F3: 0 | G3: 0 | H3: 0 | I3: 0 | J3: 0 | K3: 0 | L3: 0 | M3: 0 | N3: 0 | O3: 0 | P3: 0 | Q3: 0 | R3: 0 | S3: =IF(SUM(F3:R3)>0,1,0) -> 0 | T3: =IF(MAX(H3,J3,K3,L3,M3,N3,Q3)>0,1,0) -> 0 | U3: =IF(MAX(F3,G3,I3,O3)>0,1,0) -> 0 | V3: =IF(P3>0,1,0) -> 0 | W3: =IF(AND(B3<>"",S3=0),1,0) -> 0 | X3: =SUMPRODUCT((F3:R3=1)*0.3)+SUMPRODUCT((F3:R3=2)*0.7)+SUMPRODUCT((F3:R3=3)*1.5) -> 0
F4: 0 | G4: 0 | H4: 0 | I4: 0 | J4: 0 | K4: 0 | L4: 0 | M4: 0 | N4: 0 | O4: 0 | P4: 0 | Q4: 0 | R4: 0 | S4: =IF(SUM(F4:R4)>0,1,0) -> 0 | T4: =IF(MAX(H4,J4,K4,L4,M4,N4,Q4)>0,1,0) -> 0 | U4: =IF(MAX(F4,G4,I4,O4)>0,1,0) -> 0 | V4: =IF(P4>0,1,0) -> 0 | W4: =IF(AND(B4<>"",S4=0),1,0) -> 0 | X4: =SUMPRODUCT((F4:R4=1)*0.3)+SUMPRODUCT((F4:R4=2)*0.7)+SUMPRODUCT((F4:R4=3)*1.5) -> 0
F5: 0 | G5: 0 | H5: 0 | I5: 0 | J5: 0 | K5: 0 | L5: 0 | M5: 0 | N5: 0 | O5: 0 | P5: 0 | Q5: 0 | R5: 0 | S5: =IF(SUM(F5:R5)>0,1,0) -> 0 | T5: =IF(MAX(H5,J5,K5,L5,M5,N5,Q5)>0,1,0) -> 0 | U5: =IF(MAX(F5,G5,I5,O5)>0,1,0) -> 0 | V5: =IF(P5>0,1,0) -> 0 | W5: =IF(AND(B5<>"",S5=0),1,0) -> 0 | X5: =SUMPRODUCT((F5:R5=1)*0.3)+SUMPRODUCT((F5:R5=2)*0.7)+SUMPRODUCT((F5:R5=3)*1.5) -> 0
F6: 0 | G6: 0 | H6: 0 | I6: 0 | J6: 0 | K6: 0 | L6: 0 | M6: 0 | N6: 0 | O6: 0 | P6: 0 | Q6: 0 | R6: 0 | S6: =IF(SUM(F6:R6)>0,1,0) -> 0 | T6: =IF(MAX(H6,J6,K6,L6,M6,N6,Q6)>0,1,0) -> 0 | U6: =IF(MAX(F6,G6,I6,O6)>0,1,0) -> 0 | V6: =IF(P6>0,1,0) -> 0 | W6: =IF(AND(B6<>"",S6=0),1,0) -> 0 | X6: =SUMPRODUCT((F6:R6=1)*0.3)+SUMPRODUCT((F6:R6=2)*0.7)+SUMPRODUCT((F6:R6=3)*1.5) -> 0
F7: 0 | G7: 0 | H7: 0 | I7: 0 | J7: 0 | K7: 0 | L7: 0 | M7: 0 | N7: 0 | O7: 0 | P7: 0 | Q7: 0 | R7: 0 | S7: =IF(SUM(F7:R7)>0,1,0) -> 0 | T7: =IF(MAX(H7,J7,K7,L7,M7,N7,Q7)>0,1,0) -> 0 | U7: =IF(MAX(F7,G7,I7,O7)>0,1,0) -> 0 | V7: =IF(P7>0,1,0) -> 0 | W7: =IF(AND(B7<>"",S7=0),1,0) -> 0 | X7: =SUMPRODUCT((F7:R7=1)*0.3)+SUMPRODUCT((F7:R7=2)*0.7)+SUMPRODUCT((F7:R7=3)*1.5) -> 0
F8: 0 | G8: 0 | H8: 0 | I8: 0 | J8: 0 | K8: 0 | L8: 0 | M8: 0 | N8: 0 | O8: 0 | P8: 0 | Q8: 0 | R8: 0 | S8: =IF(SUM(F8:R8)>0,1,0) -> 0 | T8: =IF(MAX(H8,J8,K8,L8,M8,N8,Q8)>0,1,0) -> 0 | U8: =IF(MAX(F8,G8,I8,O8)>0,1,0) -> 0 | V8: =IF(P8>0,1,0) -> 0 | W8: =IF(AND(B8<>"",S8=0),1,0) -> 0 | X8: =SUMPRODUCT((F8:R8=1)*0.3)+SUMPRODUCT((F8:R8=2)*0.7)+SUMPRODUCT((F8:R8=3)*1.5) -> 0
F9: 0 | G9: 0 | H9: 0 | I9: 0 | J9: 0 | K9: 0 | L9: 0 | M9: 0 | N9: 0 | O9: 0 | P9: 0 | Q9: 0 | R9: 0 | S9: =IF(SUM(F9:R9)>0,1,0) -> 0 | T9: =IF(MAX(H9,J9,K9,L9,M9,N9,Q9)>0,1,0) -> 0 | U9: =IF(MAX(F9,G9,I9,O9)>0,1,0) -> 0 | V9: =IF(P9>0,1,0) -> 0 | W9: =IF(AND(B9<>"",S9=0),1,0) -> 0 | X9: =SUMPRODUCT((F9:R9=1)*0.3)+SUMPRODUCT((F9:R9=2)*0.7)+SUMPRODUCT((F9:R9=3)*1.5) -> 0
F10: 0 | G10: 0 | H10: 0 | I10: 0 | J10: 0 | K10: 0 | L10: 0 | M10: 0 | N10: 0 | O10: 0 | P10: 0 | Q10: 0 | R10: 0 | S10: =IF(SUM(F10:R10)>0,1,0) -> 0 | T10: =IF(MAX(H10,J10,K10,L10,M10,N10,Q10)>0,1,0) -> 0 | U10: =IF(MAX(F10,G10,I10,O10)>0,1,0) -> 0 | V10: =IF(P10>0,1,0) -> 0 | W10: =IF(AND(B10<>"",S10=0),1,0) -> 0 | X10: =SUMPRODUCT((F10:R10=1)*0.3)+SUMPRODUCT((F10:R10=2)*0.7)+SUMPRODUCT((F10:R10=3)*1.5) -> 0
F11: 0 | G11: 0 | H11: 0 | I11: 0 | J11: 0 | K11: 0 | L11: 0 | M11: 0 | N11: 0 | O11: 0 | P11: 0 | Q11: 0 | R11: 0 | S11: =IF(SUM(F11:R11)>0,1,0) -> 0 | T11: =IF(MAX(H11,J11,K11,L11,M11,N11,Q11)>0,1,0) -> 0 | U11: =IF(MAX(F11,G11,I11,O11)>0,1,0) -> 0 | V11: =IF(P11>0,1,0) -> 0 | W11: =IF(AND(B11<>"",S11=0),1,0) -> 0 | X11: =SUMPRODUCT((F11:R11=1)*0.3)+SUMPRODUCT((F11:R11=2)*0.7)+SUMPRODUCT((F11:R11=3)*1.5) -> 0
F12: 0 | G12: 0 | H12: 0 | I12: 0 | J12: 0 | K12: 0 | L12: 0 | M12: 0 | N12: 0 | O12: 0 | P12: 0 | Q12: 0 | R12: 0 | S12: =IF(SUM(F12:R12)>0,1,0) -> 0 | T12: =IF(MAX(H12,J12,K12,L12,M12,N12,Q12)>0,1,0) -> 0 | U12: =IF(MAX(F12,G12,I12,O12)>0,1,0) -> 0 | V12: =IF(P12>0,1,0) -> 0 | W12: =IF(AND(B12<>"",S12=0),1,0) -> 0 | X12: =SUMPRODUCT((F12:R12=1)*0.3)+SUMPRODUCT((F12:R12=2)*0.7)+SUMPRODUCT((F12:R12=3)*1.5) -> 0
F13: 0 | G13: 0 | H13: 0 | I13: 0 | J13: 0 | K13: 0 | L13: 0 | M13: 0 | N13: 0 | O13: 0 | P13: 0 | Q13: 0 | R13: 0 | S13: =IF(SUM(F13:R13)>0,1,0) -> 0 | T13: =IF(MAX(H13,J13,K13,L13,M13,N13,Q13)>0,1,0) -> 0 | U13: =IF(MAX(F13,G13,I13,O13)>0,1,0) -> 0 | V13: =IF(P13>0,1,0) -> 0 | W13: =IF(AND(B13<>"",S13=0),1,0) -> 0 | X13: =SUMPRODUCT((F13:R13=1)*0.3)+SUMPRODUCT((F13:R13=2)*0.7)+SUMPRODUCT((F13:R13=3)*1.5) -> 0
F14: 0 | G14: 0 | H14: 0 | I14: 0 | J14: 0 | K14: 0 | L14: 0 | M14: 0 | N14: 0 | O14: 0 | P14: 0 | Q14: 0 | R14: 0 | S14: =IF(SUM(F14:R14)>0,1,0) -> 0 | T14: =IF(MAX(H14,J14,K14,L14,M14,N14,Q14)>0,1,0) -> 0 | U14: =IF(MAX(F14,G14,I14,O14)>0,1,0) -> 0 | V14: =IF(P14>0,1,0) -> 0 | W14: =IF(AND(B14<>"",S14=0),1,0) -> 0 | X14: =SUMPRODUCT((F14:R14=1)*0.3)+SUMPRODUCT((F14:R14=2)*0.7)+SUMPRODUCT((F14:R14=3)*1.5) -> 0
... F203: 0 | G203: 0 | H203: 0 | I203: 0 | J203: 0 | K203: 0 | L203: 0 | M203: 0 | N203: 0 | O203: 0 | P203: 0 | Q203: 0 | R203: 0 | S203: =IF(SUM(F203:R203)>0,1,0) -> 0 | T203: =IF(MAX(H203,J203,K203,L203,M203,N203,Q203)>0,1,0) -> 0 | U203: =IF(MAX(F203,G203,I203,O203)>0,1,0) -> 0 | V203: =IF(P203>0,1,0) -> 0 | W203: =IF(AND(B203<>"",S203=0),1,0) -> 0 | X203: =SUMPRODUCT((F203:R203=1)*0.3)+SUMPRODUCT((F203:R203=2)*0.7)+SUMPRODUCT((F203:R203=3)*1.5) -> 0

Sheet ④ 정성 평가
A1: 장면 단위 정성 평가 (각 항목 0~2점)
A2: 장면 ID | B2: 장면 설명 | C2: 대사 흐름 | D2: 속마음·이탤릭 | E2: 설정 반영 | F2: 의역 품질 | G2: 문장 구성 | H2: 검수자 만족도(0~5) | I2: 검수 시간(분) | J2: % 점수로 변환 | K2: 비고
J3: =IFERROR((C3/2*3+D3/2*2+E3/2*2+F3/2*3+G3/2*3),0) -> 0
J4: =IFERROR((C4/2*3+D4/2*2+E4/2*2+F4/2*3+G4/2*3),0) -> 0
J5: =IFERROR((C5/2*3+D5/2*2+E5/2*2+F5/2*3+G5/2*3),0) -> 0
J6: =IFERROR((C6/2*3+D6/2*2+E6/2*2+F6/2*3+G6/2*3),0) -> 0
J7: =IFERROR((C7/2*3+D7/2*2+E7/2*2+F7/2*3+G7/2*3),0) -> 0
J8: =IFERROR((C8/2*3+D8/2*2+E8/2*2+F8/2*3+G8/2*3),0) -> 0
J9: =IFERROR((C9/2*3+D9/2*2+E9/2*2+F9/2*3+G9/2*3),0) -> 0
J10: =IFERROR((C10/2*3+D10/2*2+E10/2*2+F10/2*3+G10/2*3),0) -> 0
J11: =IFERROR((C11/2*3+D11/2*2+E11/2*2+F11/2*3+G11/2*3),0) -> 0
J12: =IFERROR((C12/2*3+D12/2*2+E12/2*2+F12/2*3+G12/2*3),0) -> 0
J13: =IFERROR((C13/2*3+D13/2*2+E13/2*2+F13/2*3+G13/2*3),0) -> 0
J14: =IFERROR((C14/2*3+D14/2*2+E14/2*2+F14/2*3+G14/2*3),0) -> 0
... J32: =IFERROR((C32/2*3+D32/2*2+E32/2*2+F32/2*3+G32/2*3),0) -> 0
A34: 평균/합계 | C34: =IFERROR(AVERAGE(C3:C32),0) -> 0 | D34: =IFERROR(AVERAGE(D3:D32),0) -> 0 | E34: =IFERROR(AVERAGE(E3:E32),0) -> 0 | F34: =IFERROR(AVERAGE(F3:F32),0) -> 0 | G34: =IFERROR(AVERAGE(G3:G32),0) -> 0 | H34: =IFERROR(AVERAGE(H3:H32),0) -> 0 | I34: =IFERROR(AVERAGE(I3:I32),0) -> 0 | J34: =IFERROR(AVERAGE(J3:J32),0) -> 0

Sheet ⑤ 결과 대시보드
A1: 결과 대시보드
A2: ③ 평가 입력 시트의 데이터를 기반으로 자동 산출됩니다.
A4: 프롬프트 버전 | B4: v1.0 | C4: 평가 일자
A6: 정량 지표
A7: 지표 | B7: v2 기준 | C7: 실제 값 | D7: 판정 | E7: 비고
A8: 총 수정률 (%) | B8: ≤ 45 | C8: =IFERROR(SUM('③ 평가 입력'!S3:S200)/COUNTA('③ 평가 입력'!B3:B203)*100,0) -> 0 | D8: =IF(C8="","",IF(C8<=45,"통과","미달")) -> 통과
A9: 의미 오류 수정률 (%) | B9: ≤ 17 | C9: =IFERROR(SUM('③ 평가 입력'!T3:T200)/COUNTA('③ 평가 입력'!B3:B203)*100,0) -> 0 | D9: =IF(C9="","",IF(C9<=17,"통과","미달")) -> 통과
A10: 형식 오류 수정률 (%) | B10: ≤ 12 | C10: =IFERROR(SUM('③ 평가 입력'!U3:U200)/COUNTA('③ 평가 입력'!B3:B203)*100,0) -> 0 | D10: =IF(C10="","",IF(C10<=12,"통과","미달")) -> 통과
A11: 시제 오류 발생률 (%) | B11: ≤ 8 | C11: =IFERROR(SUM('③ 평가 입력'!V3:V200)/COUNTA('③ 평가 입력'!B3:B203)*100,0) -> 0 | D11: =IF(C11="","",IF(C11<=8,"통과","미달")) -> 통과
A12: 수정 없이 넘긴 문장 비율 (%) | B12: ≥ 35 | C12: =IFERROR(SUM('③ 평가 입력'!W3:W200)/COUNTA('③ 평가 입력'!B3:B203)*100,0) -> 0 | D12: =IF(C12="","",IF(C12>=35,"통과","미달")) -> 미달
A14: 카테고리별 발생률 (강도≥1 문장 비율)
A15: # | B15: 카테고리 | C15: 발생 건수 | D15: 발생률 (%) | E15: 비고
A16: 1 | B16: 오타·표기 | C16: =COUNTIF('③ 평가 입력'!F3:F200,">=1") -> 0 | D16: =IFERROR(C16/COUNTA('③ 평가 입력'!B3:B203)*100,0) -> 0
A17: 2 | B17: 문법 | C17: =COUNTIF('③ 평가 입력'!G3:G200,">=1") -> 0 | D17: =IFERROR(C17/COUNTA('③ 평가 입력'!B3:B203)*100,0) -> 0
A18: 3 | B18: 오역 | C18: =COUNTIF('③ 평가 입력'!H3:H200,">=1") -> 0 | D18: =IFERROR(C18/COUNTA('③ 평가 입력'!B3:B203)*100,0) -> 0
A19: 4 | B19: 문체 종결형 | C19: =COUNTIF('③ 평가 입력'!I3:I200,">=1") -> 0 | D19: =IFERROR(C19/COUNTA('③ 평가 입력'!B3:B203)*100,0) -> 0
A20: 5 | B20: 경어·호칭 | C20: =COUNTIF('③ 평가 입력'!J3:J200,">=1") -> 0 | D20: =IFERROR(C20/COUNTA('③ 평가 입력'!B3:B203)*100,0) -> 0
A21: 6 | B21: 1·2인칭 | C21: =COUNTIF('③ 평가 입력'!K3:K200,">=1") -> 0 | D21: =IFERROR(C21/COUNTA('③ 평가 입력'!B3:B203)*100,0) -> 0
A22: 7 | B22: 오노마토페 | C22: =COUNTIF('③ 평가 입력'!L3:L200,">=1") -> 0 | D22: =IFERROR(C22/COUNTA('③ 평가 입력'!B3:B203)*100,0) -> 0
A23: 8 | B23: 설정·세계관 | C23: =COUNTIF('③ 평가 입력'!M3:M200,">=1") -> 0 | D23: =IFERROR(C23/COUNTA('③ 평가 입력'!B3:B203)*100,0) -> 0
A24: 9 | B24: 직역체 | C24: =COUNTIF('③ 평가 입력'!N3:N200,">=1") -> 0 | D24: =IFERROR(C24/COUNTA('③ 평가 입력'!B3:B203)*100,0) -> 0
A25: 10 | B25: 스타일·표기 | C25: =COUNTIF('③ 평가 입력'!O3:O200,">=1") -> 0 | D25: =IFERROR(C25/COUNTA('③ 평가 입력'!B3:B203)*100,0) -> 0
A26: 11 | B26: 시제·시점 | C26: =COUNTIF('③ 평가 입력'!P3:P200,">=1") -> 0 | D26: =IFERROR(C26/COUNTA('③ 평가 입력'!B3:B203)*100,0) -> 0
A27: 12 | B27: 일관성·문화 | C27: =COUNTIF('③ 평가 입력'!Q3:Q200,">=1") -> 0 | D27: =IFERROR(C27/COUNTA('③ 평가 입력'!B3:B203)*100,0) -> 0
A28: 13 | B28: 기타 | C28: =COUNTIF('③ 평가 입력'!R3:R200,">=1") -> 0 | D28: =IFERROR(C28/COUNTA('③ 평가 입력'!B3:B203)*100,0) -> 0
A30: 정성 평가 가산점
A31: 평균 % 점수 (가산점) | B31: ='④ 정성 평가'!J34 -> 0 | C31: 실질 수정률 (%) | D31: =MAX(0,C8-B31) -> 0
A33: 최종 판정
A34: 판정 | B34: =IF(COUNTIF(D8:D12,"미달")=0,"✅ 통과",IF(AND(COUNTIF(D8:D12,"미달")=1,D31<=45,C9>17=FALSE()),"⚠ 조건부 통과",IF(OR(COUNTIF(D8:D12,"미달")>=2,C9>17=TRUE()),"❌ 실패","⚠ 조건부 통과"))) -> ⚠ 조건부 통과

Sheet ⑥ 버전 비교
A1: 버전 비교 (v1 기준값 vs v1.x 개선안)
A2: 각 버전의 ⑤ 결과 대시보드 수치를 수동으로 옮겨 적습니다. 변화량(현재−v1)이 2%p 이상 나빠지면 "나빠짐" 표시가 자동으로 나타납니다.
A4: 지표 | B4: v1 (기준값) | C4: v1.x (현재) | D4: 변화량 (현재−v1) | E4: 방향 | F4: 나빠짐 표시 | G4: v2 기준 | H4: 판정
A5: 총 수정률 (%) | D5: =IFERROR(C5-B5,"") -> 0 | E5: =IF(D5="","",IF(D5<0,"개선",IF(D5>0,"악화","유지"))) -> 유지 | F5: =IF(D5="","",IF(D5>=2,"⚠ 나빠짐","")) | G5: ≤ 45 | H5: =IF(C5="","",IF(C5<=VALUE(SUBSTITUTE(G5,"≤ ","")),"통과","미달"))
A6: 의미 오류 수정률 (%) | D6: =IFERROR(C6-B6,"") -> 0 | E6: =IF(D6="","",IF(D6<0,"개선",IF(D6>0,"악화","유지"))) -> 유지 | F6: =IF(D6="","",IF(D6>=2,"⚠ 나빠짐","")) | G6: ≤ 17 | H6: =IF(C6="","",IF(C6<=VALUE(SUBSTITUTE(G6,"≤ ","")),"통과","미달"))
A7: 형식 오류 수정률 (%) | D7: =IFERROR(C7-B7,"") -> 0 | E7: =IF(D7="","",IF(D7<0,"개선",IF(D7>0,"악화","유지"))) -> 유지 | F7: =IF(D7="","",IF(D7>=2,"⚠ 나빠짐","")) | G7: ≤ 12 | H7: =IF(C7="","",IF(C7<=VALUE(SUBSTITUTE(G7,"≤ ","")),"통과","미달"))
A8: 시제 오류 발생률 (%) | D8: =IFERROR(C8-B8,"") -> 0 | E8: =IF(D8="","",IF(D8<0,"개선",IF(D8>0,"악화","유지"))) -> 유지 | F8: =IF(D8="","",IF(D8>=2,"⚠ 나빠짐","")) | G8: ≤ 8 | H8: =IF(C8="","",IF(C8<=VALUE(SUBSTITUTE(G8,"≤ ","")),"통과","미달"))
A9: 수정 없이 넘긴 비율 (%) | D9: =IFERROR(C9-B9,"") -> 0 | E9: =IF(D9="","",IF(D9>0,"개선",IF(D9<0,"악화","유지"))) -> 유지 | F9: =IF(D9="","",IF(D9<=-2,"⚠ 나빠짐","")) | G9: ≥ 35 | H9: =IF(C9="","",IF(C9>=VALUE(SUBSTITUTE(G9,"≥ ","")),"통과","미달"))
A11: 카테고리별 발생률 비교 (%)
A12: # | B12: 카테고리 | C12: v1 | D12: v1.x | E12: 변화량 | F12: 방향 | G12: 나빠짐 | H12: 비고
A13: 1 | B13: 오타·표기 | E13: =IFERROR(D13-C13,"") -> 0 | F13: =IF(E13="","",IF(E13<0,"개선",IF(E13>0,"악화","유지"))) -> 유지 | G13: =IF(E13="","",IF(E13>=2,"⚠ 나빠짐",""))
A14: 2 | B14: 문법 | E14: =IFERROR(D14-C14,"") -> 0 | F14: =IF(E14="","",IF(E14<0,"개선",IF(E14>0,"악화","유지"))) -> 유지 | G14: =IF(E14="","",IF(E14>=2,"⚠ 나빠짐",""))
A15: 3 | B15: 오역 | E15: =IFERROR(D15-C15,"") -> 0 | F15: =IF(E15="","",IF(E15<0,"개선",IF(E15>0,"악화","유지"))) -> 유지 | G15: =IF(E15="","",IF(E15>=2,"⚠ 나빠짐",""))
A16: 4 | B16: 문체 종결형 | E16: =IFERROR(D16-C16,"") -> 0 | F16: =IF(E16="","",IF(E16<0,"개선",IF(E16>0,"악화","유지"))) -> 유지 | G16: =IF(E16="","",IF(E16>=2,"⚠ 나빠짐",""))
A17: 5 | B17: 경어·호칭 | E17: =IFERROR(D17-C17,"") -> 0 | F17: =IF(E17="","",IF(E17<0,"개선",IF(E17>0,"악화","유지"))) -> 유지 | G17: =IF(E17="","",IF(E17>=2,"⚠ 나빠짐",""))
A18: 6 | B18: 1·2인칭 | E18: =IFERROR(D18-C18,"") -> 0 | F18: =IF(E18="","",IF(E18<0,"개선",IF(E18>0,"악화","유지"))) -> 유지 | G18: =IF(E18="","",IF(E18>=2,"⚠ 나빠짐",""))
A19: 7 | B19: 오노마토페 | E19: =IFERROR(D19-C19,"") -> 0 | F19: =IF(E19="","",IF(E19<0,"개선",IF(E19>0,"악화","유지"))) -> 유지 | G19: =IF(E19="","",IF(E19>=2,"⚠ 나빠짐",""))
A20: 8 | B20: 설정·세계관 | E20: =IFERROR(D20-C20,"") -> 0 | F20: =IF(E20="","",IF(E20<0,"개선",IF(E20>0,"악화","유지"))) -> 유지 | G20: =IF(E20="","",IF(E20>=2,"⚠ 나빠짐",""))
A21: 9 | B21: 직역체 | E21: =IFERROR(D21-C21,"") -> 0 | F21: =IF(E21="","",IF(E21<0,"개선",IF(E21>0,"악화","유지"))) -> 유지 | G21: =IF(E21="","",IF(E21>=2,"⚠ 나빠짐",""))
A22: 10 | B22: 스타일·표기 | E22: =IFERROR(D22-C22,"") -> 0 | F22: =IF(E22="","",IF(E22<0,"개선",IF(E22>0,"악화","유지"))) -> 유지 | G22: =IF(E22="","",IF(E22>=2,"⚠ 나빠짐",""))
A23: 11 | B23: 시제·시점 | E23: =IFERROR(D23-C23,"") -> 0 | F23: =IF(E23="","",IF(E23<0,"개선",IF(E23>0,"악화","유지"))) -> 유지 | G23: =IF(E23="","",IF(E23>=2,"⚠ 나빠짐",""))
A24: 12 | B24: 일관성·문화 | E24: =IFERROR(D24-C24,"") -> 0 | F24: =IF(E24="","",IF(E24<0,"개선",IF(E24>0,"악화","유지"))) -> 유지 | G24: =IF(E24="","",IF(E24>=2,"⚠ 나빠짐",""))
A25: 13 | B25: 기타 | E25: =IFERROR(D25-C25,"") -> 0 | F25: =IF(E25="","",IF(E25<0,"개선",IF(E25>0,"악화","유지"))) -> 유지 | G25: =IF(E25="","",IF(E25>=2,"⚠ 나빠짐",""))

Sheet ⑦ 기타 사례 누적
A1: "기타" 분류 사례 누적 (신규 카테고리 후보 발굴용)
A2: ③ 평가 입력 시트에서 "13.기타"로 분류된 사례를 모아둡니다. 5건 이상 반복되는 패턴이 보이면 신규 카테고리화를 검토합니다.
A3: 일자 | B3: 버전 | C3: 원문 | D3: MT본 | E3: 문제 패턴 요약 | F3: 분류 후보

Sheet ⑧ 평가자 일치율
A1: 평가자 일치율 측정 (본 평가 진입 전 필수)
A2: 평가자 2~3명이 동일한 30문장을 따로 평가한 결과를 입력하면 일치율이 자동 계산됩니다. 카테고리 일치율 70% 이상이 본 평가 진입 조건입니다.
A4: 사용 방법
A5: 1 | B5: 샘플 30문장을 평가용 원문에서 무작위로 추출해 C·D열에 붙여넣기
A6: 2 | B6: 평가자 2~3명이 각자 따로(상의 금지) 자기 영역(E~G / H~J / K~M 열)에 입력
A7: 3 | B7: 한 문장당 가장 큰 문제 카테고리 1개와 강도(0~3) 입력 / 문제 없으면 카테고리 0, 강도 0
A8: 4 | B8: 모두 입력 끝나면 N열에 일치 여부가 자동 표시됨
A9: 5 | B9: 하단 결과 영역에서 카테고리 일치율 확인 → 70% 이상이면 본 평가 진입 가능
A10: 6 | B10: 70% 미만이면 어긋난 문장(N열에 ✗ 표시) 검토 → 정의 보강 후 다른 30문장으로 재측정
A12: 평가자 정보
A13: 평가자 A 이름 | C13: 평가자 B 이름 | E13: 평가자 C 이름 (선택) | G13: 측정 일자
A15: 문장 # | B15: 원문 (한국어) | C15: MT본 (일본어) | D15: 평가자 A | F15: 평가자 B | H15: 평가자 C | J15: 카테고리 일치 | K15: 강도 일치 | L15: 어긋난 사유 (선택)
D16: 카테고리 | E16: 강도 | F16: 카테고리 | G16: 강도 | H16: 카테고리 | I16: 강도
A17: 1 | B17: 응원하는 상대가 무대에 올라왔다고 방정맞게 아는 척하지 않는 것은 귀족다우면서도 그다웠다. | C17: 応援する相手が舞台に上がったからといって、軽薄に知ったかぶりをしないのは貴族らしくもあり、彼らしい振る舞いだ。 | D17: 3 | E17: 1 | J17: =IF(OR(D17="",F17=""),"",IF(H17="",IF(D17=F17,"○","✗"),IF(AND(D17=F17,F17=H17),"○","✗"))) | K17: =IF(J17="✗","✗",IF(OR(E17="",G17=""),"",IF(I17="",IF(E17=G17,"○","✗"),IF(AND(E17=G17,G17=I17),"○","✗"))))
A18: 2 | B18: “항복이라고 외치거나 한쪽이 전투 불능이 되었다고 판단하면 대결은 종료됩니다. 제한 시간은 없습니다. 종이 울리면 바로 시작하시면 됩니다.” | C18: 「降伏と叫ぶか、一方が戦闘不能になったと判断されれば試合は終了となります。制限時間はありません。鐘が鳴ればすぐに始めてください」 | D18: 9 | E18: 1 | J18: =IF(OR(D18="",F18=""),"",IF(H18="",IF(D18=F18,"○","✗"),IF(AND(D18=F18,F18=H18),"○","✗"))) | K18: =IF(J18="✗","✗",IF(OR(E18="",G18=""),"",IF(I18="",IF(E18=G18,"○","✗"),IF(AND(E18=G18,G18=I18),"○","✗"))))
A19: 3 | B19: 댕! 짧고 묵직한 종소리가 울려 퍼졌다. | C19: ゴーンと、短く重々しい鐘の音が響き渡る。 | D19: 9 | E19: 1 | J19: =IF(OR(D19="",F19=""),"",IF(H19="",IF(D19=F19,"○","✗"),IF(AND(D19=F19,F19=H19),"○","✗"))) | K19: =IF(J19="✗","✗",IF(OR(E19="",G19=""),"",IF(I19="",IF(E19=G19,"○","✗"),IF(AND(E19=G19,G19=I19),"○","✗"))))
A20: 4 | B20: 잠시 침묵, 그리고. “와아아아아!” 관중석으로부터 거센 함성이 튀어나왔다. | C20: しばしの沈黙が流れ、そして。 「ワアアアア！」 観客席から激しい歓声が沸き起こる。 | D20: 9 | E20: 2 | J20: =IF(OR(D20="",F20=""),"",IF(H20="",IF(D20=F20,"○","✗"),IF(AND(D20=F20,F20=H20),"○","✗"))) | K20: =IF(J20="✗","✗",IF(OR(E20="",G20=""),"",IF(I20="",IF(E20=G20,"○","✗"),IF(AND(E20=G20,G20=I20),"○","✗"))))
A21: 5 | B21: 피를 본 관중들은 흥분하여 하이드란 이름을 미친 듯이 연호했다. | C21: 血を見た観客たちは興奮し、ハイドという名前を狂ったように連呼する。 | D21: 9 | E21: 1 | J21: =IF(OR(D21="",F21=""),"",IF(H21="",IF(D21=F21,"○","✗"),IF(AND(D21=F21,F21=H21),"○","✗"))) | K21: =IF(J21="✗","✗",IF(OR(E21="",G21=""),"",IF(I21="",IF(E21=G21,"○","✗"),IF(AND(E21=G21,G21=I21),"○","✗"))))
A22: 6 | B22: 얕잡아 보기 좋은 외모의 이 소년이 보인 반전은 가히 충격적이었다. | C22: 侮りやすい外見のこの少年が見せた反転は、まさに衝撃的である。 | D22: 9 | E22: 1 | J22: =IF(OR(D22="",F22=""),"",IF(H22="",IF(D22=F22,"○","✗"),IF(AND(D22=F22,F22=H22),"○","✗"))) | K22: =IF(J22="✗","✗",IF(OR(E22="",G22=""),"",IF(I22="",IF(E22=G22,"○","✗"),IF(AND(E22=G22,G22=I22),"○","✗"))))
A23: 7 | B23: “……하이드란 소년, 저런 실력을 가지고 있는 녀석일 줄은.” | C23: 「……ハイドという少年、あのような実力を持っている奴だったとは」 | D23: 9 | E23: 1 | J23: =IF(OR(D23="",F23=""),"",IF(H23="",IF(D23=F23,"○","✗"),IF(AND(D23=F23,F23=H23),"○","✗"))) | K23: =IF(J23="✗","✗",IF(OR(E23="",G23=""),"",IF(I23="",IF(E23=G23,"○","✗"),IF(AND(E23=G23,G23=I23),"○","✗"))))
A24: 8 | B24: 웬 뜬구름 잡는 소리만 줄줄 적혀 있으니 무슨 뜻인지 당최 알 수가 없다. | C24: 雲を掴むようなことばかりつらつらと書かれており、どういう意味なのか全く分からない。 | D24: 9 | E24: 1 | J24: =IF(OR(D24="",F24=""),"",IF(H24="",IF(D24=F24,"○","✗"),IF(AND(D24=F24,F24=H24),"○","✗"))) | K24: =IF(J24="✗","✗",IF(OR(E24="",G24=""),"",IF(I24="",IF(E24=G24,"○","✗"),IF(AND(E24=G24,G24=I24),"○","✗"))))
A25: 9 | B25: “저런 곳이 저곳 하나만은 아닐 텐데. 넌 어떻게 찾았지?” | C25: 「あんな場所があそこ一つだけではないはずだが。お前はどうやって見つけたんだ？」 | D25: 9 | E25: 2 | J25: =IF(OR(D25="",F25=""),"",IF(H25="",IF(D25=F25,"○","✗"),IF(AND(D25=F25,F25=H25),"○","✗"))) | K25: =IF(J25="✗","✗",IF(OR(E25="",G25=""),"",IF(I25="",IF(E25=G25,"○","✗"),IF(AND(E25=G25,G25=I25),"○","✗"))))
A26: 10 | J26: =IF(OR(D26="",F26=""),"",IF(H26="",IF(D26=F26,"○","✗"),IF(AND(D26=F26,F26=H26),"○","✗"))) | K26: =IF(J26="✗","✗",IF(OR(E26="",G26=""),"",IF(I26="",IF(E26=G26,"○","✗"),IF(AND(E26=G26,G26=I26),"○","✗"))))
A27: 11 | J27: =IF(OR(D27="",F27=""),"",IF(H27="",IF(D27=F27,"○","✗"),IF(AND(D27=F27,F27=H27),"○","✗"))) | K27: =IF(J27="✗","✗",IF(OR(E27="",G27=""),"",IF(I27="",IF(E27=G27,"○","✗"),IF(AND(E27=G27,G27=I27),"○","✗"))))
A28: 12 | J28: =IF(OR(D28="",F28=""),"",IF(H28="",IF(D28=F28,"○","✗"),IF(AND(D28=F28,F28=H28),"○","✗"))) | K28: =IF(J28="✗","✗",IF(OR(E28="",G28=""),"",IF(I28="",IF(E28=G28,"○","✗"),IF(AND(E28=G28,G28=I28),"○","✗"))))
A29: 13 | J29: =IF(OR(D29="",F29=""),"",IF(H29="",IF(D29=F29,"○","✗"),IF(AND(D29=F29,F29=H29),"○","✗"))) | K29: =IF(J29="✗","✗",IF(OR(E29="",G29=""),"",IF(I29="",IF(E29=G29,"○","✗"),IF(AND(E29=G29,G29=I29),"○","✗"))))
A30: 14 | J30: =IF(OR(D30="",F30=""),"",IF(H30="",IF(D30=F30,"○","✗"),IF(AND(D30=F30,F30=H30),"○","✗"))) | K30: =IF(J30="✗","✗",IF(OR(E30="",G30=""),"",IF(I30="",IF(E30=G30,"○","✗"),IF(AND(E30=G30,G30=I30),"○","✗"))))
A31: 15 | J31: =IF(OR(D31="",F31=""),"",IF(H31="",IF(D31=F31,"○","✗"),IF(AND(D31=F31,F31=H31),"○","✗"))) | K31: =IF(J31="✗","✗",IF(OR(E31="",G31=""),"",IF(I31="",IF(E31=G31,"○","✗"),IF(AND(E31=G31,G31=I31),"○","✗"))))
A32: 16 | J32: =IF(OR(D32="",F32=""),"",IF(H32="",IF(D32=F32,"○","✗"),IF(AND(D32=F32,F32=H32),"○","✗"))) | K32: =IF(J32="✗","✗",IF(OR(E32="",G32=""),"",IF(I32="",IF(E32=G32,"○","✗"),IF(AND(E32=G32,G32=I32),"○","✗"))))
A33: 17 | J33: =IF(OR(D33="",F33=""),"",IF(H33="",IF(D33=F33,"○","✗"),IF(AND(D33=F33,F33=H33),"○","✗"))) | K33: =IF(J33="✗","✗",IF(OR(E33="",G33=""),"",IF(I33="",IF(E33=G33,"○","✗"),IF(AND(E33=G33,G33=I33),"○","✗"))))
A34: 18 | J34: =IF(OR(D34="",F34=""),"",IF(H34="",IF(D34=F34,"○","✗"),IF(AND(D34=F34,F34=H34),"○","✗"))) | K34: =IF(J34="✗","✗",IF(OR(E34="",G34=""),"",IF(I34="",IF(E34=G34,"○","✗"),IF(AND(E34=G34,G34=I34),"○","✗"))))
A35: 19 | J35: =IF(OR(D35="",F35=""),"",IF(H35="",IF(D35=F35,"○","✗"),IF(AND(D35=F35,F35=H35),"○","✗"))) | K35: =IF(J35="✗","✗",IF(OR(E35="",G35=""),"",IF(I35="",IF(E35=G35,"○","✗"),IF(AND(E35=G35,G35=I35),"○","✗"))))
A36: 20 | J36: =IF(OR(D36="",F36=""),"",IF(H36="",IF(D36=F36,"○","✗"),IF(AND(D36=F36,F36=H36),"○","✗"))) | K36: =IF(J36="✗","✗",IF(OR(E36="",G36=""),"",IF(I36="",IF(E36=G36,"○","✗"),IF(AND(E36=G36,G36=I36),"○","✗"))))
A37: 21 | J37: =IF(OR(D37="",F37=""),"",IF(H37="",IF(D37=F37,"○","✗"),IF(AND(D37=F37,F37=H37),"○","✗"))) | K37: =IF(J37="✗","✗",IF(OR(E37="",G37=""),"",IF(I37="",IF(E37=G37,"○","✗"),IF(AND(E37=G37,G37=I37),"○","✗"))))
... A66: 50 | J66: =IF(OR(D66="",F66=""),"",IF(H66="",IF(D66=F66,"○","✗"),IF(AND(D66=F66,F66=H66),"○","✗"))) | K66: =IF(J66="✗","✗",IF(OR(E66="",G66=""),"",IF(I66="",IF(E66=G66,"○","✗"),IF(AND(E66=G66,G66=I66),"○","✗"))))
A68: 일치율 결과
A69: 항목 | B69: 평가 기준 | C69: 실제 값 | D69: 판정 | E69: 설명
A70: 평가 완료 문장 수 | B70: 30개 권장 | C70: =COUNTIF(J17:J66,"○")+COUNTIF(J17:J66,"✗") -> 0 | D70: 참고 | E70: 30문장 모두 평가가 끝나야 정확한 일치율이 산출됩니다
A71: 카테고리 일치율 (%) | B71: ≥ 70% | C71: =IFERROR(COUNTIF(J17:J66,"○")/(COUNTIF(J17:J66,"○")+COUNTIF(J17:J66,"✗"))*100,0) -> 0 | D71: =IF(C71="","",IF(C71>=70,"✅ 본 평가 진입 가능",IF(C71>=50,"⚠ 합의 부족 - 보강 후 재측정","❌ 평가 불가 - 정의 재검토"))) -> ❌ 평가 불가 - 정의 재검토 | E71: 평가자들이 같은 카테고리로 분류한 비율. 70% 이상이 본 평가 진입 조건
A72: 강도 일치율 (%) | B72: ≥ 60% | C72: =IFERROR(COUNTIF(K17:K66,"○")/(COUNTIF(K17:K66,"○")+COUNTIF(K17:K66,"✗"))*100,0) -> 0 | D72: =IF(C72="","",IF(C72>=60,"✅ 충분","⚠ 강도 합의 부족 - 본 평가 영향 미미하나 보강 권장")) -> ⚠ 강도 합의 부족 - 본 평가 영향 미미하나 보강 권장 | E72: 카테고리가 일치한 문장 중 강도 점수까지 같은 비율. 60% 이상이면 충분
...

Sheet ⑨ 본 평가 비교
A1: 본 평가 결과 비교 (평가자 A · B 결과 자동 비교 및 합산)
A2: 각 평가자가 자기 사본 시트에서 작성한 결과(F~R열의 카테고리별 강도)를 이 시트에 그대로 붙여넣으면 문장별 일치 여부와 합의 권장값이 자동 산출됩니다.
A4: 사용 방법
A5: 1 | B5: 평가자 A·B가 각자 ③ 평가 입력 시트 사본에서 600문장(또는 평가용 분량)을 따로 평가합니다.
A6: 2 | B6: 평가가 끝나면 각자의 시트에서 카테고리별 강도(F~R 13개 열)를 복사합니다.
A7: 3 | B7: 이 시트의 평가자 A 영역(E~Q열)과 평가자 B 영역(R~AD열)에 각각 붙여넣기 합니다.
A8: 4 | B8: AE열에 카테고리 일치 여부, AF열에 강도 일치 여부가 자동 표시됩니다.
A9: 5 | B9: AG열에 합의 권장 강도(평균값)가 자동 산출됩니다. 합의 회의 후 최종값을 ③ 평가 입력 시트(최종본)에 옮겨 적습니다.
A10: 6 | B10: 하단 결과 영역에서 본 평가 중 일치율(70%/60% 기준)을 확인합니다. 미달이면 데이터 무효 → 재평가 필요.
A12: 문장 # | B12: 원문 (한국어) | C12: MT본 (일본어) | D12: 검수본 (참고) | E12: 평가자 A — 카테고리별 강도 (0~3) | R12: 평가자 B — 카테고리별 강도 (0~3) | AE12: 카테고리 일치 | AF12: 강도 일치 | AG12: 합의 권장 강도 합계 | AH12: 비고 / 합의 메모
E13: 1.오타 | F13: 2.문법 | G13: 3.오역 | H13: 4.문체 | I13: 5.경어 | J13: 6.인칭 | K13: 7.오노마 | L13: 8.설정 | M13: 9.직역 | N13: 10.스타일 | O13: 11.시제 | P13: 12.일관 | Q13: 13.기타 | R13: 1.오타 | S13: 2.문법 | T13: 3.오역 | U13: 4.문체 | V13: 5.경어 | W13: 6.인칭 | X13: 7.오노마 | Y13: 8.설정 | Z13: 9.직역 | AA13: 10.스타일 | AB13: 11.시제 | AC13: 12.일관 | AD13: 13.기타
A14: 1 | AE14: =IF(AND(B14="",E14="",R14=""),"",IF(SUMPRODUCT(((E14:Q14>=1)<>(R14:AD14>=1))*1)=0,"○","✗")) | AF14: =IF(AE14="","",IF(AE14="✗","✗",IF(SUMPRODUCT((E14:Q14<>R14:AD14)*1)=0,"○","✗"))) | AG14: =IF(AND(SUM(E14:Q14)=0,SUM(R14:AD14)=0),0,(SUM(E14:Q14)+SUM(R14:AD14))/2) -> 0
A15: 2 | AE15: =IF(AND(B15="",E15="",R15=""),"",IF(SUMPRODUCT(((E15:Q15>=1)<>(R15:AD15>=1))*1)=0,"○","✗")) | AF15: =IF(AE15="","",IF(AE15="✗","✗",IF(SUMPRODUCT((E15:Q15<>R15:AD15)*1)=0,"○","✗"))) | AG15: =IF(AND(SUM(E15:Q15)=0,SUM(R15:AD15)=0),0,(SUM(E15:Q15)+SUM(R15:AD15))/2) -> 0
A16: 3 | AE16: =IF(AND(B16="",E16="",R16=""),"",IF(SUMPRODUCT(((E16:Q16>=1)<>(R16:AD16>=1))*1)=0,"○","✗")) | AF16: =IF(AE16="","",IF(AE16="✗","✗",IF(SUMPRODUCT((E16:Q16<>R16:AD16)*1)=0,"○","✗"))) | AG16: =IF(AND(SUM(E16:Q16)=0,SUM(R16:AD16)=0),0,(SUM(E16:Q16)+SUM(R16:AD16))/2) -> 0
A17: 4 | AE17: =IF(AND(B17="",E17="",R17=""),"",IF(SUMPRODUCT(((E17:Q17>=1)<>(R17:AD17>=1))*1)=0,"○","✗")) | AF17: =IF(AE17="","",IF(AE17="✗","✗",IF(SUMPRODUCT((E17:Q17<>R17:AD17)*1)=0,"○","✗"))) | AG17: =IF(AND(SUM(E17:Q17)=0,SUM(R17:AD17)=0),0,(SUM(E17:Q17)+SUM(R17:AD17))/2) -> 0
A18: 5 | AE18: =IF(AND(B18="",E18="",R18=""),"",IF(SUMPRODUCT(((E18:Q18>=1)<>(R18:AD18>=1))*1)=0,"○","✗")) | AF18: =IF(AE18="","",IF(AE18="✗","✗",IF(SUMPRODUCT((E18:Q18<>R18:AD18)*1)=0,"○","✗"))) | AG18: =IF(AND(SUM(E18:Q18)=0,SUM(R18:AD18)=0),0,(SUM(E18:Q18)+SUM(R18:AD18))/2) -> 0
A19: 6 | AE19: =IF(AND(B19="",E19="",R19=""),"",IF(SUMPRODUCT(((E19:Q19>=1)<>(R19:AD19>=1))*1)=0,"○","✗")) | AF19: =IF(AE19="","",IF(AE19="✗","✗",IF(SUMPRODUCT((E19:Q19<>R19:AD19)*1)=0,"○","✗"))) | AG19: =IF(AND(SUM(E19:Q19)=0,SUM(R19:AD19)=0),0,(SUM(E19:Q19)+SUM(R19:AD19))/2) -> 0
A20: 7 | AE20: =IF(AND(B20="",E20="",R20=""),"",IF(SUMPRODUCT(((E20:Q20>=1)<>(R20:AD20>=1))*1)=0,"○","✗")) | AF20: =IF(AE20="","",IF(AE20="✗","✗",IF(SUMPRODUCT((E20:Q20<>R20:AD20)*1)=0,"○","✗"))) | AG20: =IF(AND(SUM(E20:Q20)=0,SUM(R20:AD20)=0),0,(SUM(E20:Q20)+SUM(R20:AD20))/2) -> 0
A21: 8 | AE21: =IF(AND(B21="",E21="",R21=""),"",IF(SUMPRODUCT(((E21:Q21>=1)<>(R21:AD21>=1))*1)=0,"○","✗")) | AF21: =IF(AE21="","",IF(AE21="✗","✗",IF(SUMPRODUCT((E21:Q21<>R21:AD21)*1)=0,"○","✗"))) | AG21: =IF(AND(SUM(E21:Q21)=0,SUM(R21:AD21)=0),0,(SUM(E21:Q21)+SUM(R21:AD21))/2) -> 0
A22: 9 | AE22: =IF(AND(B22="",E22="",R22=""),"",IF(SUMPRODUCT(((E22:Q22>=1)<>(R22:AD22>=1))*1)=0,"○","✗")) | AF22: =IF(AE22="","",IF(AE22="✗","✗",IF(SUMPRODUCT((E22:Q22<>R22:AD22)*1)=0,"○","✗"))) | AG22: =IF(AND(SUM(E22:Q22)=0,SUM(R22:AD22)=0),0,(SUM(E22:Q22)+SUM(R22:AD22))/2) -> 0
A23: 10 | AE23: =IF(AND(B23="",E23="",R23=""),"",IF(SUMPRODUCT(((E23:Q23>=1)<>(R23:AD23>=1))*1)=0,"○","✗")) | AF23: =IF(AE23="","",IF(AE23="✗","✗",IF(SUMPRODUCT((E23:Q23<>R23:AD23)*1)=0,"○","✗"))) | AG23: =IF(AND(SUM(E23:Q23)=0,SUM(R23:AD23)=0),0,(SUM(E23:Q23)+SUM(R23:AD23))/2) -> 0
A24: 11 | AE24: =IF(AND(B24="",E24="",R24=""),"",IF(SUMPRODUCT(((E24:Q24>=1)<>(R24:AD24>=1))*1)=0,"○","✗")) | AF24: =IF(AE24="","",IF(AE24="✗","✗",IF(SUMPRODUCT((E24:Q24<>R24:AD24)*1)=0,"○","✗"))) | AG24: =IF(AND(SUM(E24:Q24)=0,SUM(R24:AD24)=0),0,(SUM(E24:Q24)+SUM(R24:AD24))/2) -> 0
A25: 12 | AE25: =IF(AND(B25="",E25="",R25=""),"",IF(SUMPRODUCT(((E25:Q25>=1)<>(R25:AD25>=1))*1)=0,"○","✗")) | AF25: =IF(AE25="","",IF(AE25="✗","✗",IF(SUMPRODUCT((E25:Q25<>R25:AD25)*1)=0,"○","✗"))) | AG25: =IF(AND(SUM(E25:Q25)=0,SUM(R25:AD25)=0),0,(SUM(E25:Q25)+SUM(R25:AD25))/2) -> 0
... A213: 200 | AE213: =IF(AND(B213="",E213="",R213=""),"",IF(SUMPRODUCT(((E213:Q213>=1)<>(R213:AD213>=1))*1)=0,"○","✗")) | AF213: =IF(AE213="","",IF(AE213="✗","✗",IF(SUMPRODUCT((E213:Q213<>R213:AD213)*1)=0,"○","✗"))) | AG213: =IF(AND(SUM(E213:Q213)=0,SUM(R213:AD213)=0),0,(SUM(E213:Q213)+SUM(R213:AD213))/2) -> 0
A215: 본 평가 일치율 결과 (1차 게이트)
A216: 항목 | B216: 평가 기준 | C216: 실제 값 | D216: 판정 | E216: 설명
A217: 평가 완료 문장 수 | B217: 600 권장 | C217: =COUNTIF(AE14:AE213,"○")+COUNTIF(AE14:AE213,"✗") -> 0 | D217: 참고 | E217: 평가용 원문 분량(보통 600문장 권장). 두 평가자 모두 입력된 문장 수
A218: 카테고리 일치율 (%) | B218: ≥ 70% | C218: =IFERROR(COUNTIF(AE14:AE213,"○")/(COUNTIF(AE14:AE213,"○")+COUNTIF(AE14:AE213,"✗"))*100,0) -> 0 | D218: =IF(C218="","",IF(C218>=70,"✅ 1차 게이트 통과",IF(C218>=50,"⚠ 데이터 신뢰도 부족","❌ 데이터 무효"))) -> ❌ 데이터 무효 | E218: 두 평가자가 같은 카테고리로 분류한 비율. 70% 미만이면 데이터 자체 신뢰 불가
A219: 강도 일치율 (%) | B219: ≥ 60% | C219: =IFERROR(COUNTIF(AF14:AF213,"○")/(COUNTIF(AF14:AF213,"○")+COUNTIF(AF14:AF213,"✗"))*100,0) -> 0 | D219: =IF(C219="","",IF(C219>=60,"✅ 충분","⚠ 강도 합의 부족")) -> ⚠ 강도 합의 부족 | E219: 카테고리·강도가 모두 같은 문장의 비율. 60% 미만이면 강도 기준 재합의 권장
A220: 합의 필요 문장 수 | B220: 참고 | C220: =COUNTIF(AE14:AE213,"✗") -> 0 | D220: 회의 대상 | E220: 카테고리가 다른 문장 수. 이 문장들에 대해 두 평가자가 합의 회의를 진행해야 함
A222: 카테고리별 발생 빈도 (평가자 A vs B 비교)
A223: 평가자 간 카테고리별 발생 횟수가 큰 차이를 보이면, 그 카테고리에 대한 평가 기준 합의가 부족하다는 신호입니다.
A224: # | B224: 카테고리 | C224: 평가자 A 발생 | D224: 평가자 B 발생 | E224: 차이 | F224: 판정 | G224: 비고
A225: 1 | B225: 1. 오타·표기 | C225: =COUNTIF(E14:E213,">=1") -> 0 | D225: =COUNTIF(R14:R213,">=1") -> 0 | E225: =ABS(C225-D225) -> 0 | F225: =IF(AND(C225=0,D225=0),"-",IF(E225/MAX(C225,D225,1)>0.3,"⚠ 합의 부족","○")) -> -
A226: 2 | B226: 2. 문법 | C226: =COUNTIF(F14:F213,">=1") -> 0 | D226: =COUNTIF(S14:S213,">=1") -> 0 | E226: =ABS(C226-D226) -> 0 | F226: =IF(AND(C226=0,D226=0),"-",IF(E226/MAX(C226,D226,1)>0.3,"⚠ 합의 부족","○")) -> -
A227: 3 | B227: 3. 오역 | C227: =COUNTIF(G14:G213,">=1") -> 0 | D227: =COUNTIF(T14:T213,">=1") -> 0 | E227: =ABS(C227-D227) -> 0 | F227: =IF(AND(C227=0,D227=0),"-",IF(E227/MAX(C227,D227,1)>0.3,"⚠ 합의 부족","○")) -> -
A228: 4 | B228: 4. 문체 종결형 | C228: =COUNTIF(H14:H213,">=1") -> 0 | D228: =COUNTIF(U14:U213,">=1") -> 0 | E228: =ABS(C228-D228) -> 0 | F228: =IF(AND(C228=0,D228=0),"-",IF(E228/MAX(C228,D228,1)>0.3,"⚠ 합의 부족","○")) -> -
A229: 5 | B229: 5. 경어·호칭 | C229: =COUNTIF(I14:I213,">=1") -> 0 | D229: =COUNTIF(V14:V213,">=1") -> 0 | E229: =ABS(C229-D229) -> 0 | F229: =IF(AND(C229=0,D229=0),"-",IF(E229/MAX(C229,D229,1)>0.3,"⚠ 합의 부족","○")) -> -
A230: 6 | B230: 6. 1·2인칭 | C230: =COUNTIF(J14:J213,">=1") -> 0 | D230: =COUNTIF(W14:W213,">=1") -> 0 | E230: =ABS(C230-D230) -> 0 | F230: =IF(AND(C230=0,D230=0),"-",IF(E230/MAX(C230,D230,1)>0.3,"⚠ 합의 부족","○")) -> -
A231: 7 | B231: 7. 오노마토페 | C231: =COUNTIF(K14:K213,">=1") -> 0 | D231: =COUNTIF(X14:X213,">=1") -> 0 | E231: =ABS(C231-D231) -> 0 | F231: =IF(AND(C231=0,D231=0),"-",IF(E231/MAX(C231,D231,1)>0.3,"⚠ 합의 부족","○")) -> -
...
